Workbook
Name FDC_Slot_1: "'Template Setup'!$B$4"
Name FDC_Slot_10: "'Template Setup'!$B$13"
Name FDC_Slot_2: "'Template Setup'!$B$5"
Name FDC_Slot_3: "'Template Setup'!$B$6"
Name FDC_Slot_4: "'Template Setup'!$B$7"
Name FDC_Slot_5: "'Template Setup'!$B$8"
Name FDC_Slot_6: "'Template Setup'!$B$9"
Name FDC_Slot_7: "'Template Setup'!$B$10"
Name FDC_Slot_8: "'Template Setup'!$B$11"
Name FDC_Slot_9: "'Template Setup'!$B$12"

Sheet Template Setup
B1: TEMPLATE CONFIGURATION
B2: Active WO# | C2: 7383695
B3: Slot # | C3: FDC Sheet Name | E3: STEP 1: Enter FDC sheet names in column B (yellow cells)
B4: 1 | C4: =IF($C$2="","",_xlfn.LET(_xlpm.x,IFERROR(""&INDEX('Template Setup'!$C$26:$L$200, MATCH($C$2,'Template Setup'!$B$26:$B$200,0), 1),""),_xlpm.x)) -> FDC-687 | E4: STEP 1: Enter sheet names in column B (FDC-xxx or RFI-xxx)
B5: 2 | C5: =IF($C$2="","",_xlfn.LET(_xlpm.x,IFERROR(""&INDEX('Template Setup'!$C$26:$L$200, MATCH($C$2,'Template Setup'!$B$26:$B$200,0), 2),""),_xlpm.x)) | E5: STEP 2: Leave blank slots empty for unused slots
B6: 3 | C6: =IF($C$2="","",_xlfn.LET(_xlpm.x,IFERROR(""&INDEX('Template Setup'!$C$26:$L$200, MATCH($C$2,'Template Setup'!$B$26:$B$200,0), 3),""),_xlpm.x)) | E6: Column A = Qty Ordered
B7: 4 | C7: =IF($C$2="","",_xlfn.LET(_xlpm.x,IFERROR(""&INDEX('Template Setup'!$C$26:$L$200, MATCH($C$2,'Template Setup'!$B$26:$B$200,0), 4),""),_xlpm.x)) | E7: Column B = UOM
B8: 5 | C8: =IF($C$2="","",_xlfn.LET(_xlpm.x,IFERROR(""&INDEX('Template Setup'!$C$26:$L$200, MATCH($C$2,'Template Setup'!$B$26:$B$200,0), 5),""),_xlpm.x)) | E8: Column C = SI#
B9: 6 | C9: =IF($C$2="","",_xlfn.LET(_xlpm.x,IFERROR(""&INDEX('Template Setup'!$C$26:$L$200, MATCH($C$2,'Template Setup'!$B$26:$B$200,0), 6),""),_xlpm.x)) | E9: Column D = Description
B10: 7 | C10: =IF($C$2="","",_xlfn.LET(_xlpm.x,IFERROR(""&INDEX('Template Setup'!$C$26:$L$200, MATCH($C$2,'Template Setup'!$B$26:$B$200,0), 7),""),_xlpm.x)) | E10: STEP 4: Go to 'Combined Output' sheet for results
B11: 8 | C11: =IF($C$2="","",_xlfn.LET(_xlpm.x,IFERROR(""&INDEX('Template Setup'!$C$26:$L$200, MATCH($C$2,'Template Setup'!$B$26:$B$200,0), 8),""),_xlpm.x))
B12: 9 | C12: =IF($C$2="","",_xlfn.LET(_xlpm.x,IFERROR(""&INDEX('Template Setup'!$C$26:$L$200, MATCH($C$2,'Template Setup'!$B$26:$B$200,0), 9),""),_xlpm.x)) | E12: ──────────────────────────────────
B13: 10 | C13: =IF($C$2="","",_xlfn.LET(_xlpm.x,IFERROR(""&INDEX('Template Setup'!$C$26:$L$200, MATCH($C$2,'Template Setup'!$B$26:$B$200,0), 10),""),_xlpm.x)) | E13: ⚠️ IMPORTANT NOTES:
E14: • Sheet names must match EXACTLY (case-sensitive)
C15: WO # | E15: • Max 10 FDC sheets supported
C16: =IF($C$2="","",$C$2) -> 7383695 | E16: • To add new items, update 'Master Items' sheet
E17: • Empty slots are automatically ignored
E18: • Supports both FDC-xxx and RFI-xxx naming formats
E19: 📊 SHEET OVERVIEW:
E20: • Template Setup - Configure which FDCs to include
E21: • Combined Output - Auto-calculated totals
E22: • Master Items - All unique SI# items
E23: • FDC-xxx sheets - Source data sheets
A25: Select | B25: WO# | C25: Sheet1 | D25: Sheet2 | E25: Sheet3 | F25: Sheet4 | G25: Sheet5 | H25: Sheet6 | I25: Sheet7 | J25: Sheet8 | K25: Sheet9 | L25: Sheet10
A26: ☑ | B26: 7310721 | C26: FDC-488
A27: ☑ | B27: 7153798 | C27: FDC-653 | D27: FDC-655
A28: ☑ | B28: 7383692 | C28: FDC-688
A29: ☑ | B29: 7295708 | C29: FDC-565
A30: ☑ | B30: 7383695 | C30: FDC-687

Sheet Combined Output
A1: SI# | B1: Description | C1: UOM | D1: Sources | E1: Comments | F1: Rev | G1: Q_FDC1 | H1: Q_FDC2 | I1: Q_FDC3 | J1: Q_FDC4 | K1: Q_FDC5 | L1: Src1_Num | M1: Src2_Num | N1: Src3_Num | O1: Src4_Num | P1: Src5_Num | Q1: Component ID | R1: Add QTY | S1: Existing QTY | T1: Component QTY | U1: Status
A2: {=IFERROR(INDEX(_xlfn.ANCHORARRAY('Material List'!A2),,1),"")} -> 1100065 | B2: {=IFERROR(INDEX(_xlfn.ANCHORARRAY('Material List'!A2),,2),"")} -> CABLE,UG,600V,#2,CU,SINGLE | C2: {=IFERROR(INDEX(_xlfn.ANCHORARRAY('Material List'!A2),,3),"")} -> FT | D2: =IF($A2="","",_xlfn.TEXTJOIN(", ",TRUE,IF($G2>0,'Template Setup'!$C$4,""),IF($H2>0,'Template Setup'!$C$5,""),IF($I2>0,'Template Setup'!$C$6,""),IF($J2>0,'Template Setup'!$C$7,""),IF($K2>0,'Template Setup'!$C$8,""))) -> FDC-687 | E2: {=IF($A2="","",_xlfn.LET(_xlpm.sheets,CHOOSE({1,2,3,4,5},'Template Setup'!$C$4,'Template Setup'!$C$5,'Template Setup'!$C$6,'Template Setup'!$C$7,'Template Setup'!$C$8),_xlpm.nums,CHOOSE({1,2,3,4,5},$L2,$M2,$N2,$O2,$P2),_xlpm.qtys,CHOOSE({1,2,3,4,5},$G2,$H2,$I2,$J2,$K2),_xlpm.validNums,_xlfn._xlws.FILTER(_xlpm.nums,_xlpm.qtys>0),_xlpm.validSheets,_xlfn._xlws.FILTER(_xlpm.sheets,_xlpm.qtys>0),_xlpm.mx,IFERROR(MAX(_xlpm.validNums),0),IF(_xlpm.mx=0,"",INDEX(_xlpm.validSheets,MATCH(_xlpm.mx,_xlpm.validNums,0))&" (+"&$R2&")")))} -> FDC-687 (+21) | F2: =IF($E2="","","PACP-"&LEFT($E2,FIND("-",$E2)-1)&"-000"&MID($E2,FIND("-",$E2)+1,3)) -> PACP-FDC-000687 | G2: =IF($A2="","",IFERROR(SUMIF(INDIRECT("'"&'Template Setup'!$C$4&"'!C:C"),$A2,INDIRECT("'"&'Template Setup'!$C$4&"'!A:A")),0)) -> 21 | H2: =IF($A2="","",IFERROR(SUMIF(INDIRECT("'"&'Template Setup'!$C$5&"'!C:C"),$A2,INDIRECT("'"&'Template Setup'!$C$5&"'!A:A")),0)) -> 0 | I2: =IF($A2="","",IFERROR(SUMIF(INDIRECT("'"&'Template Setup'!$C$6&"'!C:C"),$A2,INDIRECT("'"&'Template Setup'!$C$6&"'!A:A")),0)) -> 0 | J2: =IF($A2="","",IFERROR(SUMIF(INDIRECT("'"&'Template Setup'!$C$7&"'!C:C"),$A2,INDIRECT("'"&'Template Setup'!$C$7&"'!A:A")),0)) -> 0 | K2: =IF($A2="","",IFERROR(SUMIF(INDIRECT("'"&'Template Setup'!$C$8&"'!C:C"),$A2,INDIRECT("'"&'Template Setup'!$C$8&"'!A:A")),0)) -> 0 | L2: =IF($A2="","",IFERROR(VALUE(MID(TRIM('Template Setup'!$C$4),FIND("-",TRIM('Template Setup'!$C$4))+1,10)),0)) -> 687 | M2: =IF($A2="","",IFERROR(VALUE(MID(TRIM('Template Setup'!$C$5),FIND("-",TRIM('Template Setup'!$C$5))+1,10)),0)) -> 0 | N2: =IF($A2="","",IFERROR(VALUE(MID(TRIM('Template Setup'!$C$6),FIND("-",TRIM('Template Setup'!$C$6))+1,10)),0)) -> 0 | O2: =IF($A2="","",IFERROR(VALUE(MID(TRIM('Template Setup'!$C$7),FIND("-",TRIM('Template Setup'!$C$7))+1,10)),0)) -> 0 | P2: =IF($A2="","",IFERROR(VALUE(MID(TRIM('Template Setup'!$C$8),FIND("-",TRIM('Template Setup'!$C$8))+1,10)),0)) -> 0 | Q2: =IF($A2="","",$A2&"-"&'Template Setup'!$C$16) -> 1100065-7383695 | R2: =IF($A2="","",SUM($G2:$K2)) -> 21 | T2: =IF($A2="","",IF(ISBLANK(S2),"",N(R2)+S2)) | U2: ☐
A3: 1300812 | B3: CONN,STIRRUP,BLTD,4-250AL/ACSR,1/0SOL | C3: EA | D3: =IF($A3="","",_xlfn.TEXTJOIN(", ",TRUE,IF($G3>0,'Template Setup'!$C$4,""),IF($H3>0,'Template Setup'!$C$5,""),IF($I3>0,'Template Setup'!$C$6,""),IF($J3>0,'Template Setup'!$C$7,""),IF($K3>0,'Template Setup'!$C$8,""))) -> FDC-687 | E3: {=IF($A3="","",_xlfn.LET(_xlpm.sheets,CHOOSE({1,2,3,4,5},'Template Setup'!$C$4,'Template Setup'!$C$5,'Template Setup'!$C$6,'Template Setup'!$C$7,'Template Setup'!$C$8),_xlpm.nums,CHOOSE({1,2,3,4,5},$L3,$M3,$N3,$O3,$P3),_xlpm.qtys,CHOOSE({1,2,3,4,5},$G3,$H3,$I3,$J3,$K3),_xlpm.validNums,_xlfn._xlws.FILTER(_xlpm.nums,_xlpm.qtys>0),_xlpm.validSheets,_xlfn._xlws.FILTER(_xlpm.sheets,_xlpm.qtys>0),_xlpm.mx,IFERROR(MAX(_xlpm.validNums),0),IF(_xlpm.mx=0,"",INDEX(_xlpm.validSheets,MATCH(_xlpm.mx,_xlpm.validNums,0))&" (+"&$R3&")")))} -> FDC-687 (+1) | F3: =IF($E3="","","PACP-"&LEFT($E3,FIND("-",$E3)-1)&"-000"&MID($E3,FIND("-",$E3)+1,3)) -> PACP-FDC-000687 | G3: =IF($A3="","",IFERROR(SUMIF(INDIRECT("'"&'Template Setup'!$C$4&"'!C:C"),$A3,INDIRECT("'"&'Template Setup'!$C$4&"'!A:A")),0)) -> 1 | H3: =IF($A3="","",IFERROR(SUMIF(INDIRECT("'"&'Template Setup'!$C$5&"'!C:C"),$A3,INDIRECT("'"&'Template Setup'!$C$5&"'!A:A")),0)) -> 0 | I3: =IF($A3="","",IFERROR(SUMIF(INDIRECT("'"&'Template Setup'!$C$6&"'!C:C"),$A3,INDIRECT("'"&'Template Setup'!$C$6&"'!A:A")),0)) -> 0 | J3: =IF($A3="","",IFERROR(SUMIF(INDIRECT("'"&'Template Setup'!$C$7&"'!C:C"),$A3,INDIRECT("'"&'Template Setup'!$C$7&"'!A:A")),0)) -> 0 | K3: =IF($A3="","",IFERROR(SUMIF(INDIRECT("'"&'Template Setup'!$C$8&"'!C:C"),$A3,INDIRECT("'"&'Template Setup'!$C$8&"'!A:A")),0)) -> 0 | L3: =IF($A3="","",IFERROR(VALUE(MID(TRIM('Template Setup'!$C$4),FIND("-",TRIM('Template Setup'!$C$4))+1,10)),0)) -> 687 | M3: =IF($A3="","",IFERROR(VALUE(MID(TRIM('Template Setup'!$C$5),FIND("-",TRIM('Template Setup'!$C$5))+1,10)),0)) -> 0 | N3: =IF($A3="","",IFERROR(VALUE(MID(TRIM('Template Setup'!$C$6),FIND("-",TRIM('Template Setup'!$C$6))+1,10)),0)) -> 0 | O3: =IF($A3="","",IFERROR(VALUE(MID(TRIM('Template Setup'!$C$7),FIND("-",TRIM('Template Setup'!$C$7))+1,10)),0)) -> 0 | P3: =IF($A3="","",IFERROR(VALUE(MID(TRIM('Template Setup'!$C$8),FIND("-",TRIM('Template Setup'!$C$8))+1,10)),0)) -> 0 | Q3: =IF($A3="","",$A3&"-"&'Template Setup'!$C$16) -> 1300812-7383695 | R3: =IF($A3="","",SUM($G3:$K3)) -> 1 | T3: =IF($A3="","",IF(ISBLANK(S3),"",N(R3)+S3)) | U3: ☐
A4: 4500354 | B4: XFMR,POLE,25,7.2,120/240,DT,ARR | C4: EA | D4: =IF($A4="","",_xlfn.TEXTJOIN(", ",TRUE,IF($G4>0,'Template Setup'!$C$4,""),IF($H4>0,'Template Setup'!$C$5,""),IF($I4>0,'Template Setup'!$C$6,""),IF($J4>0,'Template Setup'!$C$7,""),IF($K4>0,'Template Setup'!$C$8,""))) -> FDC-687 | E4: {=IF($A4="","",_xlfn.LET(_xlpm.sheets,CHOOSE({1,2,3,4,5},'Template Setup'!$C$4,'Template Setup'!$C$5,'Template Setup'!$C$6,'Template Setup'!$C$7,'Template Setup'!$C$8),_xlpm.nums,CHOOSE({1,2,3,4,5},$L4,$M4,$N4,$O4,$P4),_xlpm.qtys,CHOOSE({1,2,3,4,5},$G4,$H4,$I4,$J4,$K4),_xlpm.validNums,_xlfn._xlws.FILTER(_xlpm.nums,_xlpm.qtys>0),_xlpm.validSheets,_xlfn._xlws.FILTER(_xlpm.sheets,_xlpm.qtys>0),_xlpm.mx,IFERROR(MAX(_xlpm.validNums),0),IF(_xlpm.mx=0,"",INDEX(_xlpm.validSheets,MATCH(_xlpm.mx,_xlpm.validNums,0))&" (+"&$R4&")")))} -> FDC-687 (+1) | F4: =IF($E4="","","PACP-"&LEFT($E4,FIND("-",$E4)-1)&"-000"&MID($E4,FIND("-",$E4)+1,3)) -> PACP-FDC-000687 | G4: =IF($A4="","",IFERROR(SUMIF(INDIRECT("'"&'Template Setup'!$C$4&"'!C:C"),$A4,INDIRECT("'"&'Template Setup'!$C$4&"'!A:A")),0)) -> 1 | H4: =IF($A4="","",IFERROR(SUMIF(INDIRECT("'"&'Template Setup'!$C$5&"'!C:C"),$A4,INDIRECT("'"&'Template Setup'!$C$5&"'!A:A")),0)) -> 0 | I4: =IF($A4="","",IFERROR(SUMIF(INDIRECT("'"&'Template Setup'!$C$6&"'!C:C"),$A4,INDIRECT("'"&'Template Setup'!$C$6&"'!A:A")),0)) -> 0 | J4: =IF($A4="","",IFERROR(SUMIF(INDIRECT("'"&'Template Setup'!$C$7&"'!C:C"),$A4,INDIRECT("'"&'Template Setup'!$C$7&"'!A:A")),0)) -> 0 | K4: =IF($A4="","",IFERROR(SUMIF(INDIRECT("'"&'Template Setup'!$C$8&"'!C:C"),$A4,INDIRECT("'"&'Template Setup'!$C$8&"'!A:A")),0)) -> 0 | L4: =IF($A4="","",IFERROR(VALUE(MID(TRIM('Template Setup'!$C$4),FIND("-",TRIM('Template Setup'!$C$4))+1,10)),0)) -> 687 | M4: =IF($A4="","",IFERROR(VALUE(MID(TRIM('Template Setup'!$C$5),FIND("-",TRIM('Template Setup'!$C$5))+1,10)),0)) -> 0 | N4: =IF($A4="","",IFERROR(VALUE(MID(TRIM('Template Setup'!$C$6),FIND("-",TRIM('Template Setup'!$C$6))+1,10)),0)) -> 0 | O4: =IF($A4="","",IFERROR(VALUE(MID(TRIM('Template Setup'!$C$7),FIND("-",TRIM('Template Setup'!$C$7))+1,10)),0)) -> 0 | P4: =IF($A4="","",IFERROR(VALUE(MID(TRIM('Template Setup'!$C$8),FIND("-",TRIM('Template Setup'!$C$8))+1,10)),0)) -> 0 | Q4: =IF($A4="","",$A4&"-"&'Template Setup'!$C$16) -> 4500354-7383695 | R4: =IF($A4="","",SUM($G4:$K4)) -> 1 | T4: =IF($A4="","",IF(ISBLANK(S4),"",N(R4)+S4)) | U4: ☐
A5: 4601902 | B5: CLAMP,HOTLINE,#8SOL-2/0STR,#8-2/0 CU | C5: EA | D5: =IF($A5="","",_xlfn.TEXTJOIN(", ",TRUE,IF($G5>0,'Template Setup'!$C$4,""),IF($H5>0,'Template Setup'!$C$5,""),IF($I5>0,'Template Setup'!$C$6,""),IF($J5>0,'Template Setup'!$C$7,""),IF($K5>0,'Template Setup'!$C$8,""))) -> FDC-687 | E5: {=IF($A5="","",_xlfn.LET(_xlpm.sheets,CHOOSE({1,2,3,4,5},'Template Setup'!$C$4,'Template Setup'!$C$5,'Template Setup'!$C$6,'Template Setup'!$C$7,'Template Setup'!$C$8),_xlpm.nums,CHOOSE({1,2,3,4,5},$L5,$M5,$N5,$O5,$P5),_xlpm.qtys,CHOOSE({1,2,3,4,5},$G5,$H5,$I5,$J5,$K5),_xlpm.validNums,_xlfn._xlws.FILTER(_xlpm.nums,_xlpm.qtys>0),_xlpm.validSheets,_xlfn._xlws.FILTER(_xlpm.sheets,_xlpm.qtys>0),_xlpm.mx,IFERROR(MAX(_xlpm.validNums),0),IF(_xlpm.mx=0,"",INDEX(_xlpm.validSheets,MATCH(_xlpm.mx,_xlpm.validNums,0))&" (+"&$R5&")")))} -> FDC-687 (+1) | F5: =IF($E5="","","PACP-"&LEFT($E5,FIND("-",$E5)-1)&"-000"&MID($E5,FIND("-",$E5)+1,3)) -> PACP-FDC-000687 | G5: =IF($A5="","",IFERROR(SUMIF(INDIRECT("'"&'Template Setup'!$C$4&"'!C:C"),$A5,INDIRECT("'"&'Template Setup'!$C$4&"'!A:A")),0)) -> 1 | H5: =IF($A5="","",IFERROR(SUMIF(INDIRECT("'"&'Template Setup'!$C$5&"'!C:C"),$A5,INDIRECT("'"&'Template Setup'!$C$5&"'!A:A")),0)) -> 0 | I5: =IF($A5="","",IFERROR(SUMIF(INDIRECT("'"&'Template Setup'!$C$6&"'!C:C"),$A5,INDIRECT("'"&'Template Setup'!$C$6&"'!A:A")),0)) -> 0 | J5: =IF($A5="","",IFERROR(SUMIF(INDIRECT("'"&'Template Setup'!$C$7&"'!C:C"),$A5,INDIRECT("'"&'Template Setup'!$C$7&"'!A:A")),0)) -> 0 | K5: =IF($A5="","",IFERROR(SUMIF(INDIRECT("'"&'Template Setup'!$C$8&"'!C:C"),$A5,INDIRECT("'"&'Template Setup'!$C$8&"'!A:A")),0)) -> 0 | L5: =IF($A5="","",IFERROR(VALUE(MID(TRIM('Template Setup'!$C$4),FIND("-",TRIM('Template Setup'!$C$4))+1,10)),0)) -> 687 | M5: =IF($A5="","",IFERROR(VALUE(MID(TRIM('Template Setup'!$C$5),FIND("-",TRIM('Template Setup'!$C$5))+1,10)),0)) -> 0 | N5: =IF($A5="","",IFERROR(VALUE(MID(TRIM('Template Setup'!$C$6),FIND("-",TRIM('Template Setup'!$C$6))+1,10)),0)) -> 0 | O5: =IF($A5="","",IFERROR(VALUE(MID(TRIM('Template Setup'!$C$7),FIND("-",TRIM('Template Setup'!$C$7))+1,10)),0)) -> 0 | P5: =IF($A5="","",IFERROR(VALUE(MID(TRIM('Template Setup'!$C$8),FIND("-",TRIM('Template Setup'!$C$8))+1,10)),0)) -> 0 | Q5: =IF($A5="","",$A5&"-"&'Template Setup'!$C$16) -> 4601902-7383695 | R5: =IF($A5="","",SUM($G5:$K5)) -> 1 | T5: =IF($A5="","",IF(ISBLANK(S5),"",N(R5)+S5)) | U5: ☐
A6: 4626107 | B6: CONN,H-TAP (#2),0.268-0.398,0.162-0.3 | C6: EA | D6: =IF($A6="","",_xlfn.TEXTJOIN(", ",TRUE,IF($G6>0,'Template Setup'!$C$4,""),IF($H6>0,'Template Setup'!$C$5,""),IF($I6>0,'Template Setup'!$C$6,""),IF($J6>0,'Template Setup'!$C$7,""),IF($K6>0,'Template Setup'!$C$8,""))) -> FDC-687 | E6: {=IF($A6="","",_xlfn.LET(_xlpm.sheets,CHOOSE({1,2,3,4,5},'Template Setup'!$C$4,'Template Setup'!$C$5,'Template Setup'!$C$6,'Template Setup'!$C$7,'Template Setup'!$C$8),_xlpm.nums,CHOOSE({1,2,3,4,5},$L6,$M6,$N6,$O6,$P6),_xlpm.qtys,CHOOSE({1,2,3,4,5},$G6,$H6,$I6,$J6,$K6),_xlpm.validNums,_xlfn._xlws.FILTER(_xlpm.nums,_xlpm.qtys>0),_xlpm.validSheets,_xlfn._xlws.FILTER(_xlpm.sheets,_xlpm.qtys>0),_xlpm.mx,IFERROR(MAX(_xlpm.validNums),0),IF(_xlpm.mx=0,"",INDEX(_xlpm.validSheets,MATCH(_xlpm.mx,_xlpm.validNums,0))&" (+"&$R6&")")))} -> FDC-687 (+2) | F6: =IF($E6="","","PACP-"&LEFT($E6,FIND("-",$E6)-1)&"-000"&MID($E6,FIND("-",$E6)+1,3)) -> PACP-FDC-000687 | G6: =IF($A6="","",IFERROR(SUMIF(INDIRECT("'"&'Template Setup'!$C$4&"'!C:C"),$A6,INDIRECT("'"&'Template Setup'!$C$4&"'!A:A")),0)) -> 2 | H6: =IF($A6="","",IFERROR(SUMIF(INDIRECT("'"&'Template Setup'!$C$5&"'!C:C"),$A6,INDIRECT("'"&'Template Setup'!$C$5&"'!A:A")),0)) -> 0 | I6: =IF($A6="","",IFERROR(SUMIF(INDIRECT("'"&'Template Setup'!$C$6&"'!C:C"),$A6,INDIRECT("'"&'Template Setup'!$C$6&"'!A:A")),0)) -> 0 | J6: =IF($A6="","",IFERROR(SUMIF(INDIRECT("'"&'Template Setup'!$C$7&"'!C:C"),$A6,INDIRECT("'"&'Template Setup'!$C$7&"'!A:A")),0)) -> 0 | K6: =IF($A6="","",IFERROR(SUMIF(INDIRECT("'"&'Template Setup'!$C$8&"'!C:C"),$A6,INDIRECT("'"&'Template Setup'!$C$8&"'!A:A")),0)) -> 0 | L6: =IF($A6="","",IFERROR(VALUE(MID(TRIM('Template Setup'!$C$4),FIND("-",TRIM('Template Setup'!$C$4))+1,10)),0)) -> 687 | M6: =IF($A6="","",IFERROR(VALUE(MID(TRIM('Template Setup'!$C$5),FIND("-",TRIM('Template Setup'!$C$5))+1,10)),0)) -> 0 | N6: =IF($A6="","",IFERROR(VALUE(MID(TRIM('Template Setup'!$C$6),FIND("-",TRIM('Template Setup'!$C$6))+1,10)),0)) -> 0 | O6: =IF($A6="","",IFERROR(VALUE(MID(TRIM('Template Setup'!$C$7),FIND("-",TRIM('Template Setup'!$C$7))+1,10)),0)) -> 0 | P6: =IF($A6="","",IFERROR(VALUE(MID(TRIM('Template Setup'!$C$8),FIND("-",TRIM('Template Setup'!$C$8))+1,10)),0)) -> 0 | Q6: =IF($A6="","",$A6&"-"&'Template Setup'!$C$16) -> 4626107-7383695 | R6: =IF($A6="","",SUM($G6:$K6)) -> 2 | T6: =IF($A6="","",IF(ISBLANK(S6),"",N(R6)+S6)) | U6: ☐
A7: 4634903 | B7: CONN,C-TAP,CU,#6SOL-#4STR,#6SOL/STR,COMP | C7: EA | D7: =IF($A7="","",_xlfn.TEXTJOIN(", ",TRUE,IF($G7>0,'Template Setup'!$C$4,""),IF($H7>0,'Template Setup'!$C$5,""),IF($I7>0,'Template Setup'!$C$6,""),IF($J7>0,'Template Setup'!$C$7,""),IF($K7>0,'Template Setup'!$C$8,""))) -> FDC-687 | E7: {=IF($A7="","",_xlfn.LET(_xlpm.sheets,CHOOSE({1,2,3,4,5},'Template Setup'!$C$4,'Template Setup'!$C$5,'Template Setup'!$C$6,'Template Setup'!$C$7,'Template Setup'!$C$8),_xlpm.nums,CHOOSE({1,2,3,4,5},$L7,$M7,$N7,$O7,$P7),_xlpm.qtys,CHOOSE({1,2,3,4,5},$G7,$H7,$I7,$J7,$K7),_xlpm.validNums,_xlfn._xlws.FILTER(_xlpm.nums,_xlpm.qtys>0),_xlpm.validSheets,_xlfn._xlws.FILTER(_xlpm.sheets,_xlpm.qtys>0),_xlpm.mx,IFERROR(MAX(_xlpm.validNums),0),IF(_xlpm.mx=0,"",INDEX(_xlpm.validSheets,MATCH(_xlpm.mx,_xlpm.validNums,0))&" (+"&$R7&")")))} -> FDC-687 (+1) | F7: =IF($E7="","","PACP-"&LEFT($E7,FIND("-",$E7)-1)&"-000"&MID($E7,FIND("-",$E7)+1,3)) -> PACP-FDC-000687 | G7: =IF($A7="","",IFERROR(SUMIF(INDIRECT("'"&'Template Setup'!$C$4&"'!C:C"),$A7,INDIRECT("'"&'Template Setup'!$C$4&"'!A:A")),0)) -> 1 | H7: =IF($A7="","",IFERROR(SUMIF(INDIRECT("'"&'Template Setup'!$C$5&"'!C:C"),$A7,INDIRECT("'"&'Template Setup'!$C$5&"'!A:A")),0)) -> 0 | I7: =IF($A7="","",IFERROR(SUMIF(INDIRECT("'"&'Template Setup'!$C$6&"'!C:C"),$A7,INDIRECT("'"&'Template Setup'!$C$6&"'!A:A")),0)) -> 0 | J7: =IF($A7="","",IFERROR(SUMIF(INDIRECT("'"&'Template Setup'!$C$7&"'!C:C"),$A7,INDIRECT("'"&'Template Setup'!$C$7&"'!A:A")),0)) -> 0 | K7: =IF($A7="","",IFERROR(SUMIF(INDIRECT("'"&'Template Setup'!$C$8&"'!C:C"),$A7,INDIRECT("'"&'Template Setup'!$C$8&"'!A:A")),0)) -> 0 | L7: =IF($A7="","",IFERROR(VALUE(MID(TRIM('Template Setup'!$C$4),FIND("-",TRIM('Template Setup'!$C$4))+1,10)),0)) -> 687 | M7: =IF($A7="","",IFERROR(VALUE(MID(TRIM('Template Setup'!$C$5),FIND("-",TRIM('Template Setup'!$C$5))+1,10)),0)) -> 0 | N7: =IF($A7="","",IFERROR(VALUE(MID(TRIM('Template Setup'!$C$6),FIND("-",TRIM('Template Setup'!$C$6))+1,10)),0)) -> 0 | O7: =IF($A7="","",IFERROR(VALUE(MID(TRIM('Template Setup'!$C$7),FIND("-",TRIM('Template Setup'!$C$7))+1,10)),0)) -> 0 | P7: =IF($A7="","",IFERROR(VALUE(MID(TRIM('Template Setup'!$C$8),FIND("-",TRIM('Template Setup'!$C$8))+1,10)),0)) -> 0 | Q7: =IF($A7="","",$A7&"-"&'Template Setup'!$C$16) -> 4634903-7383695 | R7: =IF($A7="","",SUM($G7:$K7)) -> 1 | T7: =IF($A7="","",IF(ISBLANK(S7),"",N(R7)+S7)) | U7: ☐
A8: 6117709 | B8: CONN,GRD,BRZ,XFMR,#8 SOL-#2 STR^ | C8: EA | D8: =IF($A8="","",_xlfn.TEXTJOIN(", ",TRUE,IF($G8>0,'Template Setup'!$C$4,""),IF($H8>0,'Template Setup'!$C$5,""),IF($I8>0,'Template Setup'!$C$6,""),IF($J8>0,'Template Setup'!$C$7,""),IF($K8>0,'Template Setup'!$C$8,""))) -> FDC-687 | E8: {=IF($A8="","",_xlfn.LET(_xlpm.sheets,CHOOSE({1,2,3,4,5},'Template Setup'!$C$4,'Template Setup'!$C$5,'Template Setup'!$C$6,'Template Setup'!$C$7,'Template Setup'!$C$8),_xlpm.nums,CHOOSE({1,2,3,4,5},$L8,$M8,$N8,$O8,$P8),_xlpm.qtys,CHOOSE({1,2,3,4,5},$G8,$H8,$I8,$J8,$K8),_xlpm.validNums,_xlfn._xlws.FILTER(_xlpm.nums,_xlpm.qtys>0),_xlpm.validSheets,_xlfn._xlws.FILTER(_xlpm.sheets,_xlpm.qtys>0),_xlpm.mx,IFERROR(MAX(_xlpm.validNums),0),IF(_xlpm.mx=0,"",INDEX(_xlpm.validSheets,MATCH(_xlpm.mx,_xlpm.validNums,0))&" (+"&$R8&")")))} -> FDC-687 (+1) | F8: =IF($E8="","","PACP-"&LEFT($E8,FIND("-",$E8)-1)&"-000"&MID($E8,FIND("-",$E8)+1,3)) -> PACP-FDC-000687 | G8: =IF($A8="","",IFERROR(SUMIF(INDIRECT("'"&'Template Setup'!$C$4&"'!C:C"),$A8,INDIRECT("'"&'Template Setup'!$C$4&"'!A:A")),0)) -> 1 | H8: =IF($A8="","",IFERROR(SUMIF(INDIRECT("'"&'Template Setup'!$C$5&"'!C:C"),$A8,INDIRECT("'"&'Template Setup'!$C$5&"'!A:A")),0)) -> 0 | I8: =IF($A8="","",IFERROR(SUMIF(INDIRECT("'"&'Template Setup'!$C$6&"'!C:C"),$A8,INDIRECT("'"&'Template Setup'!$C$6&"'!A:A")),0)) -> 0 | J8: =IF($A8="","",IFERROR(SUMIF(INDIRECT("'"&'Template Setup'!$C$7&"'!C:C"),$A8,INDIRECT("'"&'Template Setup'!$C$7&"'!A:A")),0)) -> 0 | K8: =IF($A8="","",IFERROR(SUMIF(INDIRECT("'"&'Template Setup'!$C$8&"'!C:C"),$A8,INDIRECT("'"&'Template Setup'!$C$8&"'!A:A")),0)) -> 0 | L8: =IF($A8="","",IFERROR(VALUE(MID(TRIM('Template Setup'!$C$4),FIND("-",TRIM('Template Setup'!$C$4))+1,10)),0)) -> 687 | M8: =IF($A8="","",IFERROR(VALUE(MID(TRIM('Template Setup'!$C$5),FIND("-",TRIM('Template Setup'!$C$5))+1,10)),0)) -> 0 | N8: =IF($A8="","",IFERROR(VALUE(MID(TRIM('Template Setup'!$C$6),FIND("-",TRIM('Template Setup'!$C$6))+1,10)),0)) -> 0 | O8: =IF($A8="","",IFERROR(VALUE(MID(TRIM('Template Setup'!$C$7),FIND("-",TRIM('Template Setup'!$C$7))+1,10)),0)) -> 0 | P8: =IF($A8="","",IFERROR(VALUE(MID(TRIM('Template Setup'!$C$8),FIND("-",TRIM('Template Setup'!$C$8))+1,10)),0)) -> 0 | Q8: =IF($A8="","",$A8&"-"&'Template Setup'!$C$16) -> 6117709-7383695 | R8: =IF($A8="","",SUM($G8:$K8)) -> 1 | T8: =IF($A8="","",IF(ISBLANK(S8),"",N(R8)+S8)) | U8: ☐
A9: 6211106 | B9: BOLT,MACH,5/8" X 12",XARM,GALV | C9: EA | D9: =IF($A9="","",_xlfn.TEXTJOIN(", ",TRUE,IF($G9>0,'Template Setup'!$C$4,""),IF($H9>0,'Template Setup'!$C$5,""),IF($I9>0,'Template Setup'!$C$6,""),IF($J9>0,'Template Setup'!$C$7,""),IF($K9>0,'Template Setup'!$C$8,""))) -> FDC-687 | E9: {=IF($A9="","",_xlfn.LET(_xlpm.sheets,CHOOSE({1,2,3,4,5},'Template Setup'!$C$4,'Template Setup'!$C$5,'Template Setup'!$C$6,'Template Setup'!$C$7,'Template Setup'!$C$8),_xlpm.nums,CHOOSE({1,2,3,4,5},$L9,$M9,$N9,$O9,$P9),_xlpm.qtys,CHOOSE({1,2,3,4,5},$G9,$H9,$I9,$J9,$K9),_xlpm.validNums,_xlfn._xlws.FILTER(_xlpm.nums,_xlpm.qtys>0),_xlpm.validSheets,_xlfn._xlws.FILTER(_xlpm.sheets,_xlpm.qtys>0),_xlpm.mx,IFERROR(MAX(_xlpm.validNums),0),IF(_xlpm.mx=0,"",INDEX(_xlpm.validSheets,MATCH(_xlpm.mx,_xlpm.validNums,0))&" (+"&$R9&")")))} -> FDC-687 (+4) | F9: =IF($E9="","","PACP-"&LEFT($E9,FIND("-",$E9)-1)&"-000"&MID($E9,FIND("-",$E9)+1,3)) -> PACP-FDC-000687 | G9: =IF($A9="","",IFERROR(SUMIF(INDIRECT("'"&'Template Setup'!$C$4&"'!C:C"),$A9,INDIRECT("'"&'Template Setup'!$C$4&"'!A:A")),0)) -> 4 | H9: =IF($A9="","",IFERROR(SUMIF(INDIRECT("'"&'Template Setup'!$C$5&"'!C:C"),$A9,INDIRECT("'"&'Template Setup'!$C$5&"'!A:A")),0)) -> 0 | I9: =IF($A9="","",IFERROR(SUMIF(INDIRECT("'"&'Template Setup'!$C$6&"'!C:C"),$A9,INDIRECT("'"&'Template Setup'!$C$6&"'!A:A")),0)) -> 0 | J9: =IF($A9="","",IFERROR(SUMIF(INDIRECT("'"&'Template Setup'!$C$7&"'!C:C"),$A9,INDIRECT("'"&'Template Setup'!$C$7&"'!A:A")),0)) -> 0 | K9: =IF($A9="","",IFERROR(SUMIF(INDIRECT("'"&'Template Setup'!$C$8&"'!C:C"),$A9,INDIRECT("'"&'Template Setup'!$C$8&"'!A:A")),0)) -> 0 | L9: =IF($A9="","",IFERROR(VALUE(MID(TRIM('Template Setup'!$C$4),FIND("-",TRIM('Template Setup'!$C$4))+1,10)),0)) -> 687 | M9: =IF($A9="","",IFERROR(VALUE(MID(TRIM('Template Setup'!$C$5),FIND("-",TRIM('Template Setup'!$C$5))+1,10)),0)) -> 0 | N9: =IF($A9="","",IFERROR(VALUE(MID(TRIM('Template Setup'!$C$6),FIND("-",TRIM('Template Setup'!$C$6))+1,10)),0)) -> 0 | O9: =IF($A9="","",IFERROR(VALUE(MID(TRIM('Template Setup'!$C$7),FIND("-",TRIM('Template Setup'!$C$7))+1,10)),0)) -> 0 | P9: =IF($A9="","",IFERROR(VALUE(MID(TRIM('Template Setup'!$C$8),FIND("-",TRIM('Template Setup'!$C$8))+1,10)),0)) -> 0 | Q9: =IF($A9="","",$A9&"-"&'Template Setup'!$C$16) -> 6211106-7383695 | R9: =IF($A9="","",SUM($G9:$K9)) -> 4 | T9: =IF($A9="","",IF(ISBLANK(S9),"",N(R9)+S9)) | U9: ☐
A10: 6269203 | B10: WASHER,SQ,CURVED,3"X3", FOR 5/8 BOLTS | C10: EA | D10: =IF($A10="","",_xlfn.TEXTJOIN(", ",TRUE,IF($G10>0,'Template Setup'!$C$4,""),IF($H10>0,'Template Setup'!$C$5,""),IF($I10>0,'Template Setup'!$C$6,""),IF($J10>0,'Template Setup'!$C$7,""),IF($K10>0,'Template Setup'!$C$8,""))) -> FDC-687 | E10: {=IF($A10="","",_xlfn.LET(_xlpm.sheets,CHOOSE({1,2,3,4,5},'Template Setup'!$C$4,'Template Setup'!$C$5,'Template Setup'!$C$6,'Template Setup'!$C$7,'Template Setup'!$C$8),_xlpm.nums,CHOOSE({1,2,3,4,5},$L10,$M10,$N10,$O10,$P10),_xlpm.qtys,CHOOSE({1,2,3,4,5},$G10,$H10,$I10,$J10,$K10),_xlpm.validNums,_xlfn._xlws.FILTER(_xlpm.nums,_xlpm.qtys>0),_xlpm.validSheets,_xlfn._xlws.FILTER(_xlpm.sheets,_xlpm.qtys>0),_xlpm.mx,IFERROR(MAX(_xlpm.validNums),0),IF(_xlpm.mx=0,"",INDEX(_xlpm.validSheets,MATCH(_xlpm.mx,_xlpm.validNums,0))&" (+"&$R10&")")))} -> FDC-687 (+4) | F10: =IF($E10="","","PACP-"&LEFT($E10,FIND("-",$E10)-1)&"-000"&MID($E10,FIND("-",$E10)+1,3)) -> PACP-FDC-000687 | G10: =IF($A10="","",IFERROR(SUMIF(INDIRECT("'"&'Template Setup'!$C$4&"'!C:C"),$A10,INDIRECT("'"&'Template Setup'!$C$4&"'!A:A")),0)) -> 4 | H10: =IF($A10="","",IFERROR(SUMIF(INDIRECT("'"&'Template Setup'!$C$5&"'!C:C"),$A10,INDIRECT("'"&'Template Setup'!$C$5&"'!A:A")),0)) -> 0 | I10: =IF($A10="","",IFERROR(SUMIF(INDIRECT("'"&'Template Setup'!$C$6&"'!C:C"),$A10,INDIRECT("'"&'Template Setup'!$C$6&"'!A:A")),0)) -> 0 | J10: =IF($A10="","",IFERROR(SUMIF(INDIRECT("'"&'Template Setup'!$C$7&"'!C:C"),$A10,INDIRECT("'"&'Template Setup'!$C$7&"'!A:A")),0)) -> 0 | K10: =IF($A10="","",IFERROR(SUMIF(INDIRECT("'"&'Template Setup'!$C$8&"'!C:C"),$A10,INDIRECT("'"&'Template Setup'!$C$8&"'!A:A")),0)) -> 0 | L10: =IF($A10="","",IFERROR(VALUE(MID(TRIM('Template Setup'!$C$4),FIND("-",TRIM('Template Setup'!$C$4))+1,10)),0)) -> 687 | M10: =IF($A10="","",IFERROR(VALUE(MID(TRIM('Template Setup'!$C$5),FIND("-",TRIM('Template Setup'!$C$5))+1,10)),0)) -> 0 | N10: =IF($A10="","",IFERROR(VALUE(MID(TRIM('Template Setup'!$C$6),FIND("-",TRIM('Template Setup'!$C$6))+1,10)),0)) -> 0 | O10: =IF($A10="","",IFERROR(VALUE(MID(TRIM('Template Setup'!$C$7),FIND("-",TRIM('Template Setup'!$C$7))+1,10)),0)) -> 0 | P10: =IF($A10="","",IFERROR(VALUE(MID(TRIM('Template Setup'!$C$8),FIND("-",TRIM('Template Setup'!$C$8))+1,10)),0)) -> 0 | Q10: =IF($A10="","",$A10&"-"&'Template Setup'!$C$16) -> 6269203-7383695 | R10: =IF($A10="","",SUM($G10:$K10)) -> 4 | T10: =IF($A10="","",IF(ISBLANK(S10),"",N(R10)+S10)) | U10: =IF($A10="","","☐") -> ☐
A11: 6279707 | B11: WASHER,SPRING,5/8",DOUBLE HELIX | C11: EA | D11: =IF($A11="","",_xlfn.TEXTJOIN(", ",TRUE,IF($G11>0,'Template Setup'!$C$4,""),IF($H11>0,'Template Setup'!$C$5,""),IF($I11>0,'Template Setup'!$C$6,""),IF($J11>0,'Template Setup'!$C$7,""),IF($K11>0,'Template Setup'!$C$8,""))) -> FDC-687 | E11: {=IF($A11="","",_xlfn.LET(_xlpm.sheets,CHOOSE({1,2,3,4,5},'Template Setup'!$C$4,'Template Setup'!$C$5,'Template Setup'!$C$6,'Template Setup'!$C$7,'Template Setup'!$C$8),_xlpm.nums,CHOOSE({1,2,3,4,5},$L11,$M11,$N11,$O11,$P11),_xlpm.qtys,CHOOSE({1,2,3,4,5},$G11,$H11,$I11,$J11,$K11),_xlpm.validNums,_xlfn._xlws.FILTER(_xlpm.nums,_xlpm.qtys>0),_xlpm.validSheets,_xlfn._xlws.FILTER(_xlpm.sheets,_xlpm.qtys>0),_xlpm.mx,IFERROR(MAX(_xlpm.validNums),0),IF(_xlpm.mx=0,"",INDEX(_xlpm.validSheets,MATCH(_xlpm.mx,_xlpm.validNums,0))&" (+"&$R11&")")))} -> FDC-687 (+4) | F11: =IF($E11="","","PACP-"&LEFT($E11,FIND("-",$E11)-1)&"-000"&MID($E11,FIND("-",$E11)+1,3)) -> PACP-FDC-000687 | G11: =IF($A11="","",IFERROR(SUMIF(INDIRECT("'"&'Template Setup'!$C$4&"'!C:C"),$A11,INDIRECT("'"&'Template Setup'!$C$4&"'!A:A")),0)) -> 4 | H11: =IF($A11="","",IFERROR(SUMIF(INDIRECT("'"&'Template Setup'!$C$5&"'!C:C"),$A11,INDIRECT("'"&'Template Setup'!$C$5&"'!A:A")),0)) -> 0 | I11: =IF($A11="","",IFERROR(SUMIF(INDIRECT("'"&'Template Setup'!$C$6&"'!C:C"),$A11,INDIRECT("'"&'Template Setup'!$C$6&"'!A:A")),0)) -> 0 | J11: =IF($A11="","",IFERROR(SUMIF(INDIRECT("'"&'Template Setup'!$C$7&"'!C:C"),$A11,INDIRECT("'"&'Template Setup'!$C$7&"'!A:A")),0)) -> 0 | K11: =IF($A11="","",IFERROR(SUMIF(INDIRECT("'"&'Template Setup'!$C$8&"'!C:C"),$A11,INDIRECT("'"&'Template Setup'!$C$8&"'!A:A")),0)) -> 0 | L11: =IF($A11="","",IFERROR(VALUE(MID(TRIM('Template Setup'!$C$4),FIND("-",TRIM('Template Setup'!$C$4))+1,10)),0)) -> 687 | M11: =IF($A11="","",IFERROR(VALUE(MID(TRIM('Template Setup'!$C$5),FIND("-",TRIM('Template Setup'!$C$5))+1,10)),0)) -> 0 | N11: =IF($A11="","",IFERROR(VALUE(MID(TRIM('Template Setup'!$C$6),FIND("-",TRIM('Template Setup'!$C$6))+1,10)),0)) -> 0 | O11: =IF($A11="","",IFERROR(VALUE(MID(TRIM('Template Setup'!$C$7),FIND("-",TRIM('Template Setup'!$C$7))+1,10)),0)) -> 0 | P11: =IF($A11="","",IFERROR(VALUE(MID(TRIM('Template Setup'!$C$8),FIND("-",TRIM('Template Setup'!$C$8))+1,10)),0)) -> 0 | Q11: =IF($A11="","",$A11&"-"&'Template Setup'!$C$16) -> 6279707-7383695 | R11: =IF($A11="","",SUM($G11:$K11)) -> 4 | T11: =IF($A11="","",IF(ISBLANK(S11),"",N(R11)+S11)) | U11: =IF($A11="","","☐") -> ☐
A12: 7991222 | B12: BRACKET,FIBERGLASS,18",CUTOUT & ARRESTER | C12: EA | D12: =IF($A12="","",_xlfn.TEXTJOIN(", ",TRUE,IF($G12>0,'Template Setup'!$C$4,""),IF($H12>0,'Template Setup'!$C$5,""),IF($I12>0,'Template Setup'!$C$6,""),IF($J12>0,'Template Setup'!$C$7,""),IF($K12>0,'Template Setup'!$C$8,""))) -> FDC-687 | E12: {=IF($A12="","",_xlfn.LET(_xlpm.sheets,CHOOSE({1,2,3,4,5},'Template Setup'!$C$4,'Template Setup'!$C$5,'Template Setup'!$C$6,'Template Setup'!$C$7,'Template Setup'!$C$8),_xlpm.nums,CHOOSE({1,2,3,4,5},$L12,$M12,$N12,$O12,$P12),_xlpm.qtys,CHOOSE({1,2,3,4,5},$G12,$H12,$I12,$J12,$K12),_xlpm.validNums,_xlfn._xlws.FILTER(_xlpm.nums,_xlpm.qtys>0),_xlpm.validSheets,_xlfn._xlws.FILTER(_xlpm.sheets,_xlpm.qtys>0),_xlpm.mx,IFERROR(MAX(_xlpm.validNums),0),IF(_xlpm.mx=0,"",INDEX(_xlpm.validSheets,MATCH(_xlpm.mx,_xlpm.validNums,0))&" (+"&$R12&")")))} -> FDC-687 (+1) | F12: =IF($E12="","","PACP-"&LEFT($E12,FIND("-",$E12)-1)&"-000"&MID($E12,FIND("-",$E12)+1,3)) -> PACP-FDC-000687 | G12: =IF($A12="","",IFERROR(SUMIF(INDIRECT("'"&'Template Setup'!$C$4&"'!C:C"),$A12,INDIRECT("'"&'Template Setup'!$C$4&"'!A:A")),0)) -> 1 | H12: =IF($A12="","",IFERROR(SUMIF(INDIRECT("'"&'Template Setup'!$C$5&"'!C:C"),$A12,INDIRECT("'"&'Template Setup'!$C$5&"'!A:A")),0)) -> 0 | I12: =IF($A12="","",IFERROR(SUMIF(INDIRECT("'"&'Template Setup'!$C$6&"'!C:C"),$A12,INDIRECT("'"&'Template Setup'!$C$6&"'!A:A")),0)) -> 0 | J12: =IF($A12="","",IFERROR(SUMIF(INDIRECT("'"&'Template Setup'!$C$7&"'!C:C"),$A12,INDIRECT("'"&'Template Setup'!$C$7&"'!A:A")),0)) -> 0 | K12: =IF($A12="","",IFERROR(SUMIF(INDIRECT("'"&'Template Setup'!$C$8&"'!C:C"),$A12,INDIRECT("'"&'Template Setup'!$C$8&"'!A:A")),0)) -> 0 | L12: =IF($A12="","",IFERROR(VALUE(MID(TRIM('Template Setup'!$C$4),FIND("-",TRIM('Template Setup'!$C$4))+1,10)),0)) -> 687 | M12: =IF($A12="","",IFERROR(VALUE(MID(TRIM('Template Setup'!$C$5),FIND("-",TRIM('Template Setup'!$C$5))+1,10)),0)) -> 0 | N12: =IF($A12="","",IFERROR(VALUE(MID(TRIM('Template Setup'!$C$6),FIND("-",TRIM('Template Setup'!$C$6))+1,10)),0)) -> 0 | O12: =IF($A12="","",IFERROR(VALUE(MID(TRIM('Template Setup'!$C$7),FIND("-",TRIM('Template Setup'!$C$7))+1,10)),0)) -> 0 | P12: =IF($A12="","",IFERROR(VALUE(MID(TRIM('Template Setup'!$C$8),FIND("-",TRIM('Template Setup'!$C$8))+1,10)),0)) -> 0 | Q12: =IF($A12="","",$A12&"-"&'Template Setup'!$C$16) -> 7991222-7383695 | R12: =IF($A12="","",SUM($G12:$K12)) -> 1 | T12: =IF($A12="","",IF(ISBLANK(S12),"",N(R12)+S12)) | U12: =IF($A12="","","☐") -> ☐
A13: 7999036 | B13: WIRE,JUMPER,#6-7 CU,SOFT-D,80 MILS COVER | C13: FT | D13: =IF($A13="","",_xlfn.TEXTJOIN(", ",TRUE,IF($G13>0,'Template Setup'!$C$4,""),IF($H13>0,'Template Setup'!$C$5,""),IF($I13>0,'Template Setup'!$C$6,""),IF($J13>0,'Template Setup'!$C$7,""),IF($K13>0,'Template Setup'!$C$8,""))) -> FDC-687 | E13: {=IF($A13="","",_xlfn.LET(_xlpm.sheets,CHOOSE({1,2,3,4,5},'Template Setup'!$C$4,'Template Setup'!$C$5,'Template Setup'!$C$6,'Template Setup'!$C$7,'Template Setup'!$C$8),_xlpm.nums,CHOOSE({1,2,3,4,5},$L13,$M13,$N13,$O13,$P13),_xlpm.qtys,CHOOSE({1,2,3,4,5},$G13,$H13,$I13,$J13,$K13),_xlpm.validNums,_xlfn._xlws.FILTER(_xlpm.nums,_xlpm.qtys>0),_xlpm.validSheets,_xlfn._xlws.FILTER(_xlpm.sheets,_xlpm.qtys>0),_xlpm.mx,IFERROR(MAX(_xlpm.validNums),0),IF(_xlpm.mx=0,"",INDEX(_xlpm.validSheets,MATCH(_xlpm.mx,_xlpm.validNums,0))&" (+"&$R13&")")))} -> FDC-687 (+24) | F13: =IF($E13="","","PACP-"&LEFT($E13,FIND("-",$E13)-1)&"-000"&MID($E13,FIND("-",$E13)+1,3)) -> PACP-FDC-000687 | G13: =IF($A13="","",IFERROR(SUMIF(INDIRECT("'"&'Template Setup'!$C$4&"'!C:C"),$A13,INDIRECT("'"&'Template Setup'!$C$4&"'!A:A")),0)) -> 24 | H13: =IF($A13="","",IFERROR(SUMIF(INDIRECT("'"&'Template Setup'!$C$5&"'!C:C"),$A13,INDIRECT("'"&'Template Setup'!$C$5&"'!A:A")),0)) -> 0 | I13: =IF($A13="","",IFERROR(SUMIF(INDIRECT("'"&'Template Setup'!$C$6&"'!C:C"),$A13,INDIRECT("'"&'Template Setup'!$C$6&"'!A:A")),0)) -> 0 | J13: =IF($A13="","",IFERROR(SUMIF(INDIRECT("'"&'Template Setup'!$C$7&"'!C:C"),$A13,INDIRECT("'"&'Template Setup'!$C$7&"'!A:A")),0)) -> 0 | K13: =IF($A13="","",IFERROR(SUMIF(INDIRECT("'"&'Template Setup'!$C$8&"'!C:C"),$A13,INDIRECT("'"&'Template Setup'!$C$8&"'!A:A")),0)) -> 0 | L13: =IF($A13="","",IFERROR(VALUE(MID(TRIM('Template Setup'!$C$4),FIND("-",TRIM('Template Setup'!$C$4))+1,10)),0)) -> 687 | M13: =IF($A13="","",IFERROR(VALUE(MID(TRIM('Template Setup'!$C$5),FIND("-",TRIM('Template Setup'!$C$5))+1,10)),0)) -> 0 | N13: =IF($A13="","",IFERROR(VALUE(MID(TRIM('Template Setup'!$C$6),FIND("-",TRIM('Template Setup'!$C$6))+1,10)),0)) -> 0 | O13: =IF($A13="","",IFERROR(VALUE(MID(TRIM('Template Setup'!$C$7),FIND("-",TRIM('Template Setup'!$C$7))+1,10)),0)) -> 0 | P13: =IF($A13="","",IFERROR(VALUE(MID(TRIM('Template Setup'!$C$8),FIND("-",TRIM('Template Setup'!$C$8))+1,10)),0)) -> 0 | Q13: =IF($A13="","",$A13&"-"&'Template Setup'!$C$16) -> 7999036-7383695 | R13: =IF($A13="","",SUM($G13:$K13)) -> 24 | T13: =IF($A13="","",IF(ISBLANK(S13),"",N(R13)+S13)) | U13: =IF($A13="","","☐") -> ☐
A14: 7999719 | B14: CUTOUT,POLYMER,27KV,100A,12KA,UNIVERSAL^ | C14: EA | D14: =IF($A14="","",_xlfn.TEXTJOIN(", ",TRUE,IF($G14>0,'Template Setup'!$C$4,""),IF($H14>0,'Template Setup'!$C$5,""),IF($I14>0,'Template Setup'!$C$6,""),IF($J14>0,'Template Setup'!$C$7,""),IF($K14>0,'Template Setup'!$C$8,""))) -> FDC-687 | E14: {=IF($A14="","",_xlfn.LET(_xlpm.sheets,CHOOSE({1,2,3,4,5},'Template Setup'!$C$4,'Template Setup'!$C$5,'Template Setup'!$C$6,'Template Setup'!$C$7,'Template Setup'!$C$8),_xlpm.nums,CHOOSE({1,2,3,4,5},$L14,$M14,$N14,$O14,$P14),_xlpm.qtys,CHOOSE({1,2,3,4,5},$G14,$H14,$I14,$J14,$K14),_xlpm.validNums,_xlfn._xlws.FILTER(_xlpm.nums,_xlpm.qtys>0),_xlpm.validSheets,_xlfn._xlws.FILTER(_xlpm.sheets,_xlpm.qtys>0),_xlpm.mx,IFERROR(MAX(_xlpm.validNums),0),IF(_xlpm.mx=0,"",INDEX(_xlpm.validSheets,MATCH(_xlpm.mx,_xlpm.validNums,0))&" (+"&$R14&")")))} -> FDC-687 (+1) | F14: =IF($E14="","","PACP-"&LEFT($E14,FIND("-",$E14)-1)&"-000"&MID($E14,FIND("-",$E14)+1,3)) -> PACP-FDC-000687 | G14: =IF($A14="","",IFERROR(SUMIF(INDIRECT("'"&'Template Setup'!$C$4&"'!C:C"),$A14,INDIRECT("'"&'Template Setup'!$C$4&"'!A:A")),0)) -> 1 | H14: =IF($A14="","",IFERROR(SUMIF(INDIRECT("'"&'Template Setup'!$C$5&"'!C:C"),$A14,INDIRECT("'"&'Template Setup'!$C$5&"'!A:A")),0)) -> 0 | I14: =IF($A14="","",IFERROR(SUMIF(INDIRECT("'"&'Template Setup'!$C$6&"'!C:C"),$A14,INDIRECT("'"&'Template Setup'!$C$6&"'!A:A")),0)) -> 0 | J14: =IF($A14="","",IFERROR(SUMIF(INDIRECT("'"&'Template Setup'!$C$7&"'!C:C"),$A14,INDIRECT("'"&'Template Setup'!$C$7&"'!A:A")),0)) -> 0 | K14: =IF($A14="","",IFERROR(SUMIF(INDIRECT("'"&'Template Setup'!$C$8&"'!C:C"),$A14,INDIRECT("'"&'Template Setup'!$C$8&"'!A:A")),0)) -> 0 | L14: =IF($A14="","",IFERROR(VALUE(MID(TRIM('Template Setup'!$C$4),FIND("-",TRIM('Template Setup'!$C$4))+1,10)),0)) -> 687 | M14: =IF($A14="","",IFERROR(VALUE(MID(TRIM('Template Setup'!$C$5),FIND("-",TRIM('Template Setup'!$C$5))+1,10)),0)) -> 0 | N14: =IF($A14="","",IFERROR(VALUE(MID(TRIM('Template Setup'!$C$6),FIND("-",TRIM('Template Setup'!$C$6))+1,10)),0)) -> 0 | O14: =IF($A14="","",IFERROR(VALUE(MID(TRIM('Template Setup'!$C$7),FIND("-",TRIM('Template Setup'!$C$7))+1,10)),0)) -> 0 | P14: =IF($A14="","",IFERROR(VALUE(MID(TRIM('Template Setup'!$C$8),FIND("-",TRIM('Template Setup'!$C$8))+1,10)),0)) -> 0 | Q14: =IF($A14="","",$A14&"-"&'Template Setup'!$C$16) -> 7999719-7383695 | R14: =IF($A14="","",SUM($G14:$K14)) -> 1 | T14: =IF($A14="","",IF(ISBLANK(S14),"",N(R14)+S14)) | U14: =IF($A14="","","☐") -> ☐
A15: 7999796 | B15: GUARD,SPRING LOADED,EQUIP BUSHING COVER^ | C15: EA | D15: =IF($A15="","",_xlfn.TEXTJOIN(", ",TRUE,IF($G15>0,'Template Setup'!$C$4,""),IF($H15>0,'Template Setup'!$C$5,""),IF($I15>0,'Template Setup'!$C$6,""),IF($J15>0,'Template Setup'!$C$7,""),IF($K15>0,'Template Setup'!$C$8,""))) -> FDC-687 | E15: {=IF($A15="","",_xlfn.LET(_xlpm.sheets,CHOOSE({1,2,3,4,5},'Template Setup'!$C$4,'Template Setup'!$C$5,'Template Setup'!$C$6,'Template Setup'!$C$7,'Template Setup'!$C$8),_xlpm.nums,CHOOSE({1,2,3,4,5},$L15,$M15,$N15,$O15,$P15),_xlpm.qtys,CHOOSE({1,2,3,4,5},$G15,$H15,$I15,$J15,$K15),_xlpm.validNums,_xlfn._xlws.FILTER(_xlpm.nums,_xlpm.qtys>0),_xlpm.validSheets,_xlfn._xlws.FILTER(_xlpm.sheets,_xlpm.qtys>0),_xlpm.mx,IFERROR(MAX(_xlpm.validNums),0),IF(_xlpm.mx=0,"",INDEX(_xlpm.validSheets,MATCH(_xlpm.mx,_xlpm.validNums,0))&" (+"&$R15&")")))} -> FDC-687 (+1) | F15: =IF($E15="","","PACP-"&LEFT($E15,FIND("-",$E15)-1)&"-000"&MID($E15,FIND("-",$E15)+1,3)) -> PACP-FDC-000687 | G15: =IF($A15="","",IFERROR(SUMIF(INDIRECT("'"&'Template Setup'!$C$4&"'!C:C"),$A15,INDIRECT("'"&'Template Setup'!$C$4&"'!A:A")),0)) -> 1 | H15: =IF($A15="","",IFERROR(SUMIF(INDIRECT("'"&'Template Setup'!$C$5&"'!C:C"),$A15,INDIRECT("'"&'Template Setup'!$C$5&"'!A:A")),0)) -> 0 | I15: =IF($A15="","",IFERROR(SUMIF(INDIRECT("'"&'Template Setup'!$C$6&"'!C:C"),$A15,INDIRECT("'"&'Template Setup'!$C$6&"'!A:A")),0)) -> 0 | J15: =IF($A15="","",IFERROR(SUMIF(INDIRECT("'"&'Template Setup'!$C$7&"'!C:C"),$A15,INDIRECT("'"&'Template Setup'!$C$7&"'!A:A")),0)) -> 0 | K15: =IF($A15="","",IFERROR(SUMIF(INDIRECT("'"&'Template Setup'!$C$8&"'!C:C"),$A15,INDIRECT("'"&'Template Setup'!$C$8&"'!A:A")),0)) -> 0 | L15: =IF($A15="","",IFERROR(VALUE(MID(TRIM('Template Setup'!$C$4),FIND("-",TRIM('Template Setup'!$C$4))+1,10)),0)) -> 687 | M15: =IF($A15="","",IFERROR(VALUE(MID(TRIM('Template Setup'!$C$5),FIND("-",TRIM('Template Setup'!$C$5))+1,10)),0)) -> 0 | N15: =IF($A15="","",IFERROR(VALUE(MID(TRIM('Template Setup'!$C$6),FIND("-",TRIM('Template Setup'!$C$6))+1,10)),0)) -> 0 | O15: =IF($A15="","",IFERROR(VALUE(MID(TRIM('Template Setup'!$C$7),FIND("-",TRIM('Template Setup'!$C$7))+1,10)),0)) -> 0 | P15: =IF($A15="","",IFERROR(VALUE(MID(TRIM('Template Setup'!$C$8),FIND("-",TRIM('Template Setup'!$C$8))+1,10)),0)) -> 0 | Q15: =IF($A15="","",$A15&"-"&'Template Setup'!$C$16) -> 7999796-7383695 | R15: =IF($A15="","",SUM($G15:$K15)) -> 1 | T15: =IF($A15="","",IF(ISBLANK(S15),"",N(R15)+S15)) | U15: =IF($A15="","","☐") -> ☐
A16: 8004492 | B16: FUSE,ELF,6A,8.3KV,27KV CUTOUT,SGL BARREL | C16: EA | D16: =IF($A16="","",_xlfn.TEXTJOIN(", ",TRUE,IF($G16>0,'Template Setup'!$C$4,""),IF($H16>0,'Template Setup'!$C$5,""),IF($I16>0,'Template Setup'!$C$6,""),IF($J16>0,'Template Setup'!$C$7,""),IF($K16>0,'Template Setup'!$C$8,""))) -> FDC-687 | E16: {=IF($A16="","",_xlfn.LET(_xlpm.sheets,CHOOSE({1,2,3,4,5},'Template Setup'!$C$4,'Template Setup'!$C$5,'Template Setup'!$C$6,'Template Setup'!$C$7,'Template Setup'!$C$8),_xlpm.nums,CHOOSE({1,2,3,4,5},$L16,$M16,$N16,$O16,$P16),_xlpm.qtys,CHOOSE({1,2,3,4,5},$G16,$H16,$I16,$J16,$K16),_xlpm.validNums,_xlfn._xlws.FILTER(_xlpm.nums,_xlpm.qtys>0),_xlpm.validSheets,_xlfn._xlws.FILTER(_xlpm.sheets,_xlpm.qtys>0),_xlpm.mx,IFERROR(MAX(_xlpm.validNums),0),IF(_xlpm.mx=0,"",INDEX(_xlpm.validSheets,MATCH(_xlpm.mx,_xlpm.validNums,0))&" (+"&$R16&")")))} -> FDC-687 (+1) | F16: =IF($E16="","","PACP-"&LEFT($E16,FIND("-",$E16)-1)&"-000"&MID($E16,FIND("-",$E16)+1,3)) -> PACP-FDC-000687 | G16: =IF($A16="","",IFERROR(SUMIF(INDIRECT("'"&'Template Setup'!$C$4&"'!C:C"),$A16,INDIRECT("'"&'Template Setup'!$C$4&"'!A:A")),0)) -> 1 | H16: =IF($A16="","",IFERROR(SUMIF(INDIRECT("'"&'Template Setup'!$C$5&"'!C:C"),$A16,INDIRECT("'"&'Template Setup'!$C$5&"'!A:A")),0)) -> 0 | I16: =IF($A16="","",IFERROR(SUMIF(INDIRECT("'"&'Template Setup'!$C$6&"'!C:C"),$A16,INDIRECT("'"&'Template Setup'!$C$6&"'!A:A")),0)) -> 0 | J16: =IF($A16="","",IFERROR(SUMIF(INDIRECT("'"&'Template Setup'!$C$7&"'!C:C"),$A16,INDIRECT("'"&'Template Setup'!$C$7&"'!A:A")),0)) -> 0 | K16: =IF($A16="","",IFERROR(SUMIF(INDIRECT("'"&'Template Setup'!$C$8&"'!C:C"),$A16,INDIRECT("'"&'Template Setup'!$C$8&"'!A:A")),0)) -> 0 | L16: =IF($A16="","",IFERROR(VALUE(MID(TRIM('Template Setup'!$C$4),FIND("-",TRIM('Template Setup'!$C$4))+1,10)),0)) -> 687 | M16: =IF($A16="","",IFERROR(VALUE(MID(TRIM('Template Setup'!$C$5),FIND("-",TRIM('Template Setup'!$C$5))+1,10)),0)) -> 0 | N16: =IF($A16="","",IFERROR(VALUE(MID(TRIM('Template Setup'!$C$6),FIND("-",TRIM('Template Setup'!$C$6))+1,10)),0)) -> 0 | O16: =IF($A16="","",IFERROR(VALUE(MID(TRIM('Template Setup'!$C$7),FIND("-",TRIM('Template Setup'!$C$7))+1,10)),0)) -> 0 | P16: =IF($A16="","",IFERROR(VALUE(MID(TRIM('Template Setup'!$C$8),FIND("-",TRIM('Template Setup'!$C$8))+1,10)),0)) -> 0 | Q16: =IF($A16="","",$A16&"-"&'Template Setup'!$C$16) -> 8004492-7383695 | R16: =IF($A16="","",SUM($G16:$K16)) -> 1 | T16: =IF($A16="","",IF(ISBLANK(S16),"",N(R16)+S16)) | U16: =IF($A16="","","☐") -> ☐
A17: 8005123 | B17: ARRESTER,SRG,NONEXPULSION,10KV,MOV | C17: EA | D17: =IF($A17="","",_xlfn.TEXTJOIN(", ",TRUE,IF($G17>0,'Template Setup'!$C$4,""),IF($H17>0,'Template Setup'!$C$5,""),IF($I17>0,'Template Setup'!$C$6,""),IF($J17>0,'Template Setup'!$C$7,""),IF($K17>0,'Template Setup'!$C$8,""))) -> FDC-687 | E17: {=IF($A17="","",_xlfn.LET(_xlpm.sheets,CHOOSE({1,2,3,4,5},'Template Setup'!$C$4,'Template Setup'!$C$5,'Template Setup'!$C$6,'Template Setup'!$C$7,'Template Setup'!$C$8),_xlpm.nums,CHOOSE({1,2,3,4,5},$L17,$M17,$N17,$O17,$P17),_xlpm.qtys,CHOOSE({1,2,3,4,5},$G17,$H17,$I17,$J17,$K17),_xlpm.validNums,_xlfn._xlws.FILTER(_xlpm.nums,_xlpm.qtys>0),_xlpm.validSheets,_xlfn._xlws.FILTER(_xlpm.sheets,_xlpm.qtys>0),_xlpm.mx,IFERROR(MAX(_xlpm.validNums),0),IF(_xlpm.mx=0,"",INDEX(_xlpm.validSheets,MATCH(_xlpm.mx,_xlpm.validNums,0))&" (+"&$R17&")")))} -> FDC-687 (+1) | F17: =IF($E17="","","PACP-"&LEFT($E17,FIND("-",$E17)-1)&"-000"&MID($E17,FIND("-",$E17)+1,3)) -> PACP-FDC-000687 | G17: =IF($A17="","",IFERROR(SUMIF(INDIRECT("'"&'Template Setup'!$C$4&"'!C:C"),$A17,INDIRECT("'"&'Template Setup'!$C$4&"'!A:A")),0)) -> 1 | H17: =IF($A17="","",IFERROR(SUMIF(INDIRECT("'"&'Template Setup'!$C$5&"'!C:C"),$A17,INDIRECT("'"&'Template Setup'!$C$5&"'!A:A")),0)) -> 0 | I17: =IF($A17="","",IFERROR(SUMIF(INDIRECT("'"&'Template Setup'!$C$6&"'!C:C"),$A17,INDIRECT("'"&'Template Setup'!$C$6&"'!A:A")),0)) -> 0 | J17: =IF($A17="","",IFERROR(SUMIF(INDIRECT("'"&'Template Setup'!$C$7&"'!C:C"),$A17,INDIRECT("'"&'Template Setup'!$C$7&"'!A:A")),0)) -> 0 | K17: =IF($A17="","",IFERROR(SUMIF(INDIRECT("'"&'Template Setup'!$C$8&"'!C:C"),$A17,INDIRECT("'"&'Template Setup'!$C$8&"'!A:A")),0)) -> 0 | L17: =IF($A17="","",IFERROR(VALUE(MID(TRIM('Template Setup'!$C$4),FIND("-",TRIM('Template Setup'!$C$4))+1,10)),0)) -> 687 | M17: =IF($A17="","",IFERROR(VALUE(MID(TRIM('Template Setup'!$C$5),FIND("-",TRIM('Template Setup'!$C$5))+1,10)),0)) -> 0 | N17: =IF($A17="","",IFERROR(VALUE(MID(TRIM('Template Setup'!$C$6),FIND("-",TRIM('Template Setup'!$C$6))+1,10)),0)) -> 0 | O17: =IF($A17="","",IFERROR(VALUE(MID(TRIM('Template Setup'!$C$7),FIND("-",TRIM('Template Setup'!$C$7))+1,10)),0)) -> 0 | P17: =IF($A17="","",IFERROR(VALUE(MID(TRIM('Template Setup'!$C$8),FIND("-",TRIM('Template Setup'!$C$8))+1,10)),0)) -> 0 | Q17: =IF($A17="","",$A17&"-"&'Template Setup'!$C$16) -> 8005123-7383695 | R17: =IF($A17="","",SUM($G17:$K17)) -> 1 | T17: =IF($A17="","",IF(ISBLANK(S17),"",N(R17)+S17)) | U17: =IF($A17="","","☐") -> ☐
A18: 8006321 | B18: COVER,CUTOUT,FR RATED,POLYMER,27KV150BIL | C18: EA | D18: =IF($A18="","",_xlfn.TEXTJOIN(", ",TRUE,IF($G18>0,'Template Setup'!$C$4,""),IF($H18>0,'Template Setup'!$C$5,""),IF($I18>0,'Template Setup'!$C$6,""),IF($J18>0,'Template Setup'!$C$7,""),IF($K18>0,'Template Setup'!$C$8,""))) -> FDC-687 | E18: {=IF($A18="","",_xlfn.LET(_xlpm.sheets,CHOOSE({1,2,3,4,5},'Template Setup'!$C$4,'Template Setup'!$C$5,'Template Setup'!$C$6,'Template Setup'!$C$7,'Template Setup'!$C$8),_xlpm.nums,CHOOSE({1,2,3,4,5},$L18,$M18,$N18,$O18,$P18),_xlpm.qtys,CHOOSE({1,2,3,4,5},$G18,$H18,$I18,$J18,$K18),_xlpm.validNums,_xlfn._xlws.FILTER(_xlpm.nums,_xlpm.qtys>0),_xlpm.validSheets,_xlfn._xlws.FILTER(_xlpm.sheets,_xlpm.qtys>0),_xlpm.mx,IFERROR(MAX(_xlpm.validNums),0),IF(_xlpm.mx=0,"",INDEX(_xlpm.validSheets,MATCH(_xlpm.mx,_xlpm.validNums,0))&" (+"&$R18&")")))} -> FDC-687 (+1) | F18: =IF($E18="","","PACP-"&LEFT($E18,FIND("-",$E18)-1)&"-000"&MID($E18,FIND("-",$E18)+1,3)) -> PACP-FDC-000687 | G18: =IF($A18="","",IFERROR(SUMIF(INDIRECT("'"&'Template Setup'!$C$4&"'!C:C"),$A18,INDIRECT("'"&'Template Setup'!$C$4&"'!A:A")),0)) -> 1 | H18: =IF($A18="","",IFERROR(SUMIF(INDIRECT("'"&'Template Setup'!$C$5&"'!C:C"),$A18,INDIRECT("'"&'Template Setup'!$C$5&"'!A:A")),0)) -> 0 | I18: =IF($A18="","",IFERROR(SUMIF(INDIRECT("'"&'Template Setup'!$C$6&"'!C:C"),$A18,INDIRECT("'"&'Template Setup'!$C$6&"'!A:A")),0)) -> 0 | J18: =IF($A18="","",IFERROR(SUMIF(INDIRECT("'"&'Template Setup'!$C$7&"'!C:C"),$A18,INDIRECT("'"&'Template Setup'!$C$7&"'!A:A")),0)) -> 0 | K18: =IF($A18="","",IFERROR(SUMIF(INDIRECT("'"&'Template Setup'!$C$8&"'!C:C"),$A18,INDIRECT("'"&'Template Setup'!$C$8&"'!A:A")),0)) -> 0 | L18: =IF($A18="","",IFERROR(VALUE(MID(TRIM('Template Setup'!$C$4),FIND("-",TRIM('Template Setup'!$C$4))+1,10)),0)) -> 687 | M18: =IF($A18="","",IFERROR(VALUE(MID(TRIM('Template Setup'!$C$5),FIND("-",TRIM('Template Setup'!$C$5))+1,10)),0)) -> 0 | N18: =IF($A18="","",IFERROR(VALUE(MID(TRIM('Template Setup'!$C$6),FIND("-",TRIM('Template Setup'!$C$6))+1,10)),0)) -> 0 | O18: =IF($A18="","",IFERROR(VALUE(MID(TRIM('Template Setup'!$C$7),FIND("-",TRIM('Template Setup'!$C$7))+1,10)),0)) -> 0 | P18: =IF($A18="","",IFERROR(VALUE(MID(TRIM('Template Setup'!$C$8),FIND("-",TRIM('Template Setup'!$C$8))+1,10)),0)) -> 0 | Q18: =IF($A18="","",$A18&"-"&'Template Setup'!$C$16) -> 8006321-7383695 | R18: =IF($A18="","",SUM($G18:$K18)) -> 1 | T18: =IF($A18="","",IF(ISBLANK(S18),"",N(R18)+S18)) | U18: =IF($A18="","","☐") -> ☐
A19: 8006513 | B19: COVER,STIRRUP,COVERED CONDUCTOR,GRAY^ | C19: EA | D19: =IF($A19="","",_xlfn.TEXTJOIN(", ",TRUE,IF($G19>0,'Template Setup'!$C$4,""),IF($H19>0,'Template Setup'!$C$5,""),IF($I19>0,'Template Setup'!$C$6,""),IF($J19>0,'Template Setup'!$C$7,""),IF($K19>0,'Template Setup'!$C$8,""))) -> FDC-687 | E19: {=IF($A19="","",_xlfn.LET(_xlpm.sheets,CHOOSE({1,2,3,4,5},'Template Setup'!$C$4,'Template Setup'!$C$5,'Template Setup'!$C$6,'Template Setup'!$C$7,'Template Setup'!$C$8),_xlpm.nums,CHOOSE({1,2,3,4,5},$L19,$M19,$N19,$O19,$P19),_xlpm.qtys,CHOOSE({1,2,3,4,5},$G19,$H19,$I19,$J19,$K19),_xlpm.validNums,_xlfn._xlws.FILTER(_xlpm.nums,_xlpm.qtys>0),_xlpm.validSheets,_xlfn._xlws.FILTER(_xlpm.sheets,_xlpm.qtys>0),_xlpm.mx,IFERROR(MAX(_xlpm.validNums),0),IF(_xlpm.mx=0,"",INDEX(_xlpm.validSheets,MATCH(_xlpm.mx,_xlpm.validNums,0))&" (+"&$R19&")")))} -> FDC-687 (+1) | F19: =IF($E19="","","PACP-"&LEFT($E19,FIND("-",$E19)-1)&"-000"&MID($E19,FIND("-",$E19)+1,3)) -> PACP-FDC-000687 | G19: =IF($A19="","",IFERROR(SUMIF(INDIRECT("'"&'Template Setup'!$C$4&"'!C:C"),$A19,INDIRECT("'"&'Template Setup'!$C$4&"'!A:A")),0)) -> 1 | H19: =IF($A19="","",IFERROR(SUMIF(INDIRECT("'"&'Template Setup'!$C$5&"'!C:C"),$A19,INDIRECT("'"&'Template Setup'!$C$5&"'!A:A")),0)) -> 0 | I19: =IF($A19="","",IFERROR(SUMIF(INDIRECT("'"&'Template Setup'!$C$6&"'!C:C"),$A19,INDIRECT("'"&'Template Setup'!$C$6&"'!A:A")),0)) -> 0 | J19: =IF($A19="","",IFERROR(SUMIF(INDIRECT("'"&'Template Setup'!$C$7&"'!C:C"),$A19,INDIRECT("'"&'Template Setup'!$C$7&"'!A:A")),0)) -> 0 | K19: =IF($A19="","",IFERROR(SUMIF(INDIRECT("'"&'Template Setup'!$C$8&"'!C:C"),$A19,INDIRECT("'"&'Template Setup'!$C$8&"'!A:A")),0)) -> 0 | L19: =IF($A19="","",IFERROR(VALUE(MID(TRIM('Template Setup'!$C$4),FIND("-",TRIM('Template Setup'!$C$4))+1,10)),0)) -> 687 | M19: =IF($A19="","",IFERROR(VALUE(MID(TRIM('Template Setup'!$C$5),FIND("-",TRIM('Template Setup'!$C$5))+1,10)),0)) -> 0 | N19: =IF($A19="","",IFERROR(VALUE(MID(TRIM('Template Setup'!$C$6),FIND("-",TRIM('Template Setup'!$C$6))+1,10)),0)) -> 0 | O19: =IF($A19="","",IFERROR(VALUE(MID(TRIM('Template Setup'!$C$7),FIND("-",TRIM('Template Setup'!$C$7))+1,10)),0)) -> 0 | P19: =IF($A19="","",IFERROR(VALUE(MID(TRIM('Template Setup'!$C$8),FIND("-",TRIM('Template Setup'!$C$8))+1,10)),0)) -> 0 | Q19: =IF($A19="","",$A19&"-"&'Template Setup'!$C$16) -> 8006513-7383695 | R19: =IF($A19="","",SUM($G19:$K19)) -> 1 | T19: =IF($A19="","",IF(ISBLANK(S19),"",N(R19)+S19)) | U19: =IF($A19="","","☐") -> ☐
D20: =IF($A20="","",_xlfn.TEXTJOIN(", ",TRUE,IF($G20>0,'Template Setup'!$C$4,""),IF($H20>0,'Template Setup'!$C$5,""),IF($I20>0,'Template Setup'!$C$6,""),IF($J20>0,'Template Setup'!$C$7,""),IF($K20>0,'Template Setup'!$C$8,""))) | E20: {=IF($A20="","",_xlfn.LET(_xlpm.sheets,CHOOSE({1,2,3,4,5},'Template Setup'!$C$4,'Template Setup'!$C$5,'Template Setup'!$C$6,'Template Setup'!$C$7,'Template Setup'!$C$8),_xlpm.nums,CHOOSE({1,2,3,4,5},$L20,$M20,$N20,$O20,$P20),_xlpm.qtys,CHOOSE({1,2,3,4,5},$G20,$H20,$I20,$J20,$K20),_xlpm.validNums,_xlfn._xlws.FILTER(_xlpm.nums,_xlpm.qtys>0),_xlpm.validSheets,_xlfn._xlws.FILTER(_xlpm.sheets,_xlpm.qtys>0),_xlpm.mx,IFERROR(MAX(_xlpm.validNums),0),IF(_xlpm.mx=0,"",INDEX(_xlpm.validSheets,MATCH(_xlpm.mx,_xlpm.validNums,0))&" (+"&$R20&")")))} | F20: =IF($E20="","","PACP-"&LEFT($E20,FIND("-",$E20)-1)&"-000"&MID($E20,FIND("-",$E20)+1,3)) | G20: =IF($A20="","",IFERROR(SUMIF(INDIRECT("'"&'Template Setup'!$C$4&"'!C:C"),$A20,INDIRECT("'"&'Template Setup'!$C$4&"'!A:A")),0)) | H20: =IF($A20="","",IFERROR(SUMIF(INDIRECT("'"&'Template Setup'!$C$5&"'!C:C"),$A20,INDIRECT("'"&'Template Setup'!$C$5&"'!A:A")),0)) | I20: =IF($A20="","",IFERROR(SUMIF(INDIRECT("'"&'Template Setup'!$C$6&"'!C:C"),$A20,INDIRECT("'"&'Template Setup'!$C$6&"'!A:A")),0)) | J20: =IF($A20="","",IFERROR(SUMIF(INDIRECT("'"&'Template Setup'!$C$7&"'!C:C"),$A20,INDIRECT("'"&'Template Setup'!$C$7&"'!A:A")),0)) | K20: =IF($A20="","",IFERROR(SUMIF(INDIRECT("'"&'Template Setup'!$C$8&"'!C:C"),$A20,INDIRECT("'"&'Template Setup'!$C$8&"'!A:A")),0)) | L20: =IF($A20="","",IFERROR(VALUE(MID(TRIM('Template Setup'!$C$4),FIND("-",TRIM('Template Setup'!$C$4))+1,10)),0)) | M20: =IF($A20="","",IFERROR(VALUE(MID(TRIM('Template Setup'!$C$5),FIND("-",TRIM('Template Setup'!$C$5))+1,10)),0)) | N20: =IF($A20="","",IFERROR(VALUE(MID(TRIM('Template Setup'!$C$6),FIND("-",TRIM('Template Setup'!$C$6))+1,10)),0)) | O20: =IF($A20="","",IFERROR(VALUE(MID(TRIM('Template Setup'!$C$7),FIND("-",TRIM('Template Setup'!$C$7))+1,10)),0)) | P20: =IF($A20="","",IFERROR(VALUE(MID(TRIM('Template Setup'!$C$8),FIND("-",TRIM('Template Setup'!$C$8))+1,10)),0)) | Q20: =IF($A20="","",$A20&"-"&'Template Setup'!$C$16) | R20: =IF($A20="","",SUM($G20:$K20)) | T20: =IF($A20="","",IF(ISBLANK(S20),"",N(R20)+S20)) | U20: =IF($A20="","","☐")
D21: =IF($A21="","",_xlfn.TEXTJOIN(", ",TRUE,IF($G21>0,'Template Setup'!$C$4,""),IF($H21>0,'Template Setup'!$C$5,""),IF($I21>0,'Template Setup'!$C$6,""),IF($J21>0,'Template Setup'!$C$7,""),IF($K21>0,'Template Setup'!$C$8,""))) | E21: {=IF($A21="","",_xlfn.LET(_xlpm.sheets,CHOOSE({1,2,3,4,5},'Template Setup'!$C$4,'Template Setup'!$C$5,'Template Setup'!$C$6,'Template Setup'!$C$7,'Template Setup'!$C$8),_xlpm.nums,CHOOSE({1,2,3,4,5},$L21,$M21,$N21,$O21,$P21),_xlpm.qtys,CHOOSE({1,2,3,4,5},$G21,$H21,$I21,$J21,$K21),_xlpm.validNums,_xlfn._xlws.FILTER(_xlpm.nums,_xlpm.qtys>0),_xlpm.validSheets,_xlfn._xlws.FILTER(_xlpm.sheets,_xlpm.qtys>0),_xlpm.mx,IFERROR(MAX(_xlpm.validNums),0),IF(_xlpm.mx=0,"",INDEX(_xlpm.validSheets,MATCH(_xlpm.mx,_xlpm.validNums,0))&" (+"&$R21&")")))} | F21: =IF($E21="","","PACP-"&LEFT($E21,FIND("-",$E21)-1)&"-000"&MID($E21,FIND("-",$E21)+1,3)) | G21: =IF($A21="","",IFERROR(SUMIF(INDIRECT("'"&'Template Setup'!$C$4&"'!C:C"),$A21,INDIRECT("'"&'Template Setup'!$C$4&"'!A:A")),0)) | H21: =IF($A21="","",IFERROR(SUMIF(INDIRECT("'"&'Template Setup'!$C$5&"'!C:C"),$A21,INDIRECT("'"&'Template Setup'!$C$5&"'!A:A")),0)) | I21: =IF($A21="","",IFERROR(SUMIF(INDIRECT("'"&'Template Setup'!$C$6&"'!C:C"),$A21,INDIRECT("'"&'Template Setup'!$C$6&"'!A:A")),0)) | J21: =IF($A21="","",IFERROR(SUMIF(INDIRECT("'"&'Template Setup'!$C$7&"'!C:C"),$A21,INDIRECT("'"&'Template Setup'!$C$7&"'!A:A")),0)) | K21: =IF($A21="","",IFERROR(SUMIF(INDIRECT("'"&'Template Setup'!$C$8&"'!C:C"),$A21,INDIRECT("'"&'Template Setup'!$C$8&"'!A:A")),0)) | L21: =IF($A21="","",IFERROR(VALUE(MID(TRIM('Template Setup'!$C$4),FIND("-",TRIM('Template Setup'!$C$4))+1,10)),0)) | M21: =IF($A21="","",IFERROR(VALUE(MID(TRIM('Template Setup'!$C$5),FIND("-",TRIM('Template Setup'!$C$5))+1,10)),0)) | N21: =IF($A21="","",IFERROR(VALUE(MID(TRIM('Template Setup'!$C$6),FIND("-",TRIM('Template Setup'!$C$6))+1,10)),0)) | O21: =IF($A21="","",IFERROR(VALUE(MID(TRIM('Template Setup'!$C$7),FIND("-",TRIM('Template Setup'!$C$7))+1,10)),0)) | P21: =IF($A21="","",IFERROR(VALUE(MID(TRIM('Template Setup'!$C$8),FIND("-",TRIM('Template Setup'!$C$8))+1,10)),0)) | Q21: =IF($A21="","",$A21&"-"&'Template Setup'!$C$16) | R21: =IF($A21="","",SUM($G21:$K21)) | T21: =IF($A21="","",IF(ISBLANK(S21),"",N(R21)+S21)) | U21: =IF($A21="","","☐")
D22: =IF($A22="","",_xlfn.TEXTJOIN(", ",TRUE,IF($G22>0,'Template Setup'!$C$4,""),IF($H22>0,'Template Setup'!$C$5,""),IF($I22>0,'Template Setup'!$C$6,""),IF($J22>0,'Template Setup'!$C$7,""),IF($K22>0,'Template Setup'!$C$8,""))) | E22: {=IF($A22="","",_xlfn.LET(_xlpm.sheets,CHOOSE({1,2,3,4,5},'Template Setup'!$C$4,'Template Setup'!$C$5,'Template Setup'!$C$6,'Template Setup'!$C$7,'Template Setup'!$C$8),_xlpm.nums,CHOOSE({1,2,3,4,5},$L22,$M22,$N22,$O22,$P22),_xlpm.qtys,CHOOSE({1,2,3,4,5},$G22,$H22,$I22,$J22,$K22),_xlpm.validNums,_xlfn._xlws.FILTER(_xlpm.nums,_xlpm.qtys>0),_xlpm.validSheets,_xlfn._xlws.FILTER(_xlpm.sheets,_xlpm.qtys>0),_xlpm.mx,IFERROR(MAX(_xlpm.validNums),0),IF(_xlpm.mx=0,"",INDEX(_xlpm.validSheets,MATCH(_xlpm.mx,_xlpm.validNums,0))&" (+"&$R22&")")))} | F22: =IF($E22="","","PACP-"&LEFT($E22,FIND("-",$E22)-1)&"-000"&MID($E22,FIND("-",$E22)+1,3)) | G22: =IF($A22="","",IFERROR(SUMIF(INDIRECT("'"&'Template Setup'!$C$4&"'!C:C"),$A22,INDIRECT("'"&'Template Setup'!$C$4&"'!A:A")),0)) | H22: =IF($A22="","",IFERROR(SUMIF(INDIRECT("'"&'Template Setup'!$C$5&"'!C:C"),$A22,INDIRECT("'"&'Template Setup'!$C$5&"'!A:A")),0)) | I22: =IF($A22="","",IFERROR(SUMIF(INDIRECT("'"&'Template Setup'!$C$6&"'!C:C"),$A22,INDIRECT("'"&'Template Setup'!$C$6&"'!A:A")),0)) | J22: =IF($A22="","",IFERROR(SUMIF(INDIRECT("'"&'Template Setup'!$C$7&"'!C:C"),$A22,INDIRECT("'"&'Template Setup'!$C$7&"'!A:A")),0)) | K22: =IF($A22="","",IFERROR(SUMIF(INDIRECT("'"&'Template Setup'!$C$8&"'!C:C"),$A22,INDIRECT("'"&'Template Setup'!$C$8&"'!A:A")),0)) | L22: =IF($A22="","",IFERROR(VALUE(MID(TRIM('Template Setup'!$C$4),FIND("-",TRIM('Template Setup'!$C$4))+1,10)),0)) | M22: =IF($A22="","",IFERROR(VALUE(MID(TRIM('Template Setup'!$C$5),FIND("-",TRIM('Template Setup'!$C$5))+1,10)),0)) | N22: =IF($A22="","",IFERROR(VALUE(MID(TRIM('Template Setup'!$C$6),FIND("-",TRIM('Template Setup'!$C$6))+1,10)),0)) | O22: =IF($A22="","",IFERROR(VALUE(MID(TRIM('Template Setup'!$C$7),FIND("-",TRIM('Template Setup'!$C$7))+1,10)),0)) | P22: =IF($A22="","",IFERROR(VALUE(MID(TRIM('Template Setup'!$C$8),FIND("-",TRIM('Template Setup'!$C$8))+1,10)),0)) | Q22: =IF($A22="","",$A22&"-"&'Template Setup'!$C$16) | R22: =IF($A22="","",SUM($G22:$K22)) | T22: =IF($A22="","",IF(ISBLANK(S22),"",N(R22)+S22)) | U22: =IF($A22="","","☐")
D23: =IF($A23="","",_xlfn.TEXTJOIN(", ",TRUE,IF($G23>0,'Template Setup'!$C$4,""),IF($H23>0,'Template Setup'!$C$5,""),IF($I23>0,'Template Setup'!$C$6,""),IF($J23>0,'Template Setup'!$C$7,""),IF($K23>0,'Template Setup'!$C$8,""))) | E23: {=IF($A23="","",_xlfn.LET(_xlpm.sheets,CHOOSE({1,2,3,4,5},'Template Setup'!$C$4,'Template Setup'!$C$5,'Template Setup'!$C$6,'Template Setup'!$C$7,'Template Setup'!$C$8),_xlpm.nums,CHOOSE({1,2,3,4,5},$L23,$M23,$N23,$O23,$P23),_xlpm.qtys,CHOOSE({1,2,3,4,5},$G23,$H23,$I23,$J23,$K23),_xlpm.validNums,_xlfn._xlws.FILTER(_xlpm.nums,_xlpm.qtys>0),_xlpm.validSheets,_xlfn._xlws.FILTER(_xlpm.sheets,_xlpm.qtys>0),_xlpm.mx,IFERROR(MAX(_xlpm.validNums),0),IF(_xlpm.mx=0,"",INDEX(_xlpm.validSheets,MATCH(_xlpm.mx,_xlpm.validNums,0))&" (+"&$R23&")")))} | F23: =IF($E23="","","PACP-"&LEFT($E23,FIND("-",$E23)-1)&"-000"&MID($E23,FIND("-",$E23)+1,3)) | G23: =IF($A23="","",IFERROR(SUMIF(INDIRECT("'"&'Template Setup'!$C$4&"'!C:C"),$A23,INDIRECT("'"&'Template Setup'!$C$4&"'!A:A")),0)) | H23: =IF($A23="","",IFERROR(SUMIF(INDIRECT("'"&'Template Setup'!$C$5&"'!C:C"),$A23,INDIRECT("'"&'Template Setup'!$C$5&"'!A:A")),0)) | I23: =IF($A23="","",IFERROR(SUMIF(INDIRECT("'"&'Template Setup'!$C$6&"'!C:C"),$A23,INDIRECT("'"&'Template Setup'!$C$6&"'!A:A")),0)) | J23: =IF($A23="","",IFERROR(SUMIF(INDIRECT("'"&'Template Setup'!$C$7&"'!C:C"),$A23,INDIRECT("'"&'Template Setup'!$C$7&"'!A:A")),0)) | K23: =IF($A23="","",IFERROR(SUMIF(INDIRECT("'"&'Template Setup'!$C$8&"'!C:C"),$A23,INDIRECT("'"&'Template Setup'!$C$8&"'!A:A")),0)) | L23: =IF($A23="","",IFERROR(VALUE(MID(TRIM('Template Setup'!$C$4),FIND("-",TRIM('Template Setup'!$C$4))+1,10)),0)) | M23: =IF($A23="","",IFERROR(VALUE(MID(TRIM('Template Setup'!$C$5),FIND("-",TRIM('Template Setup'!$C$5))+1,10)),0)) | N23: =IF($A23="","",IFERROR(VALUE(MID(TRIM('Template Setup'!$C$6),FIND("-",TRIM('Template Setup'!$C$6))+1,10)),0)) | O23: =IF($A23="","",IFERROR(VALUE(MID(TRIM('Template Setup'!$C$7),FIND("-",TRIM('Template Setup'!$C$7))+1,10)),0)) | P23: =IF($A23="","",IFERROR(VALUE(MID(TRIM('Template Setup'!$C$8),FIND("-",TRIM('Template Setup'!$C$8))+1,10)),0)) | Q23: =IF($A23="","",$A23&"-"&'Template Setup'!$C$16) | R23: =IF($A23="","",SUM($G23:$K23)) | T23: =IF($A23="","",IF(ISBLANK(S23),"",N(R23)+S23)) | U23: =IF($A23="","","☐")
D24: =IF($A24="","",_xlfn.TEXTJOIN(", ",TRUE,IF($G24>0,'Template Setup'!$C$4,""),IF($H24>0,'Template Setup'!$C$5,""),IF($I24>0,'Template Setup'!$C$6,""),IF($J24>0,'Template Setup'!$C$7,""),IF($K24>0,'Template Setup'!$C$8,""))) | E24: {=IF($A24="","",_xlfn.LET(_xlpm.sheets,CHOOSE({1,2,3,4,5},'Template Setup'!$C$4,'Template Setup'!$C$5,'Template Setup'!$C$6,'Template Setup'!$C$7,'Template Setup'!$C$8),_xlpm.nums,CHOOSE({1,2,3,4,5},$L24,$M24,$N24,$O24,$P24),_xlpm.qtys,CHOOSE({1,2,3,4,5},$G24,$H24,$I24,$J24,$K24),_xlpm.validNums,_xlfn._xlws.FILTER(_xlpm.nums,_xlpm.qtys>0),_xlpm.validSheets,_xlfn._xlws.FILTER(_xlpm.sheets,_xlpm.qtys>0),_xlpm.mx,IFERROR(MAX(_xlpm.validNums),0),IF(_xlpm.mx=0,"",INDEX(_xlpm.validSheets,MATCH(_xlpm.mx,_xlpm.validNums,0))&" (+"&$R24&")")))} | F24: =IF($E24="","","PACP-"&LEFT($E24,FIND("-",$E24)-1)&"-000"&MID($E24,FIND("-",$E24)+1,3)) | G24: =IF($A24="","",IFERROR(SUMIF(INDIRECT("'"&'Template Setup'!$C$4&"'!C:C"),$A24,INDIRECT("'"&'Template Setup'!$C$4&"'!A:A")),0)) | H24: =IF($A24="","",IFERROR(SUMIF(INDIRECT("'"&'Template Setup'!$C$5&"'!C:C"),$A24,INDIRECT("'"&'Template Setup'!$C$5&"'!A:A")),0)) | I24: =IF($A24="","",IFERROR(SUMIF(INDIRECT("'"&'Template Setup'!$C$6&"'!C:C"),$A24,INDIRECT("'"&'Template Setup'!$C$6&"'!A:A")),0)) | J24: =IF($A24="","",IFERROR(SUMIF(INDIRECT("'"&'Template Setup'!$C$7&"'!C:C"),$A24,INDIRECT("'"&'Template Setup'!$C$7&"'!A:A")),0)) | K24: =IF($A24="","",IFERROR(SUMIF(INDIRECT("'"&'Template Setup'!$C$8&"'!C:C"),$A24,INDIRECT("'"&'Template Setup'!$C$8&"'!A:A")),0)) | L24: =IF($A24="","",IFERROR(VALUE(MID(TRIM('Template Setup'!$C$4),FIND("-",TRIM('Template Setup'!$C$4))+1,10)),0)) | M24: =IF($A24="","",IFERROR(VALUE(MID(TRIM('Template Setup'!$C$5),FIND("-",TRIM('Template Setup'!$C$5))+1,10)),0)) | N24: =IF($A24="","",IFERROR(VALUE(MID(TRIM('Template Setup'!$C$6),FIND("-",TRIM('Template Setup'!$C$6))+1,10)),0)) | O24: =IF($A24="","",IFERROR(VALUE(MID(TRIM('Template Setup'!$C$7),FIND("-",TRIM('Template Setup'!$C$7))+1,10)),0)) | P24: =IF($A24="","",IFERROR(VALUE(MID(TRIM('Template Setup'!$C$8),FIND("-",TRIM('Template Setup'!$C$8))+1,10)),0)) | Q24: =IF($A24="","",$A24&"-"&'Template Setup'!$C$16) | R24: =IF($A24="","",SUM($G24:$K24)) | T24: =IF($A24="","",IF(ISBLANK(S24),"",N(R24)+S24)) | U24: =IF($A24="","","☐")
