Workbook

Sheet Template
A1: English | B1: User Selected Language
A2: REQUIRED | B2: Field is required for import
A3: OPTIONAL | B3: Field is optional for import
A4: VALIDATED | B4: Field must match master data available in application
A5: IGNORED | B5: Field not to be populated
A6: DS/CS | B6: Discipline/Commodity specific fields
A7: Note: 1. If the Project configuration allows associating Claiming scheme to WBS, then specifying Discipline/Commodity is not mandatory in presence of WBS. Discipline or Commodity will be identified based on Type 2. Columns with data type Text should be formatted as Text to see trailing zeros after decimal. | H7: Work Order # | I7: Rev | K7: Paste from MIT | L7: Paste from MIT | M7: Paste from MIT | O7: MIT # | R7: Automate? | S7: Automate? | U7: Automate?
A8: Component Id | B8: Name | C8: WBS | D8: Type | E8: Discipline/Commodity | F8: Claiming Scheme | G8: Construction commodity | H8: Project Doc # | I8: Project Doc Rev # | J8: Work package ID | K8: Quantity | L8: UoM | M8: AUX 7 | N8: Description | O8: Engineering Doc # | P8: Comments | Q8: AUX 6 | R8: Segment | S8: Area | T8: System | U8: Turnover packages
A9: Numeric | B9: Text | C9: Text | D9: Text | E9: Text | F9: Text | G9: Text | H9: Text | I9: Text | J9: Text | K9: Numeric | L9: Text | M9: Text | N9: Text | O9: Text | P9: Text | Q9: Text | R9: Text | S9: Text | T9: Text | U9: Text
B10: 200 | C10: 50 | D10: 10 | E10: 100 | H10: 0 | I10: 0 | J10: 30 | K10: 16 | L10: 255 | M10: 0 | N10: 250 | O10: 0 | P10: 200 | Q10: 0 | R10: 0 | S10: 0 | T10: 0 | U10: 0
A11: =_xlfn.XLOOKUP(B11,'Component ID-Name'!B:B,'Component ID-Name'!A:A,"") | B11: =M11&"-"&O11 -> 4634903-7383695 | C11: =_xlfn.XLOOKUP(L11,Mapping!$D$1:$D$11,Mapping!$A$1:$A$11) -> 1116 | D11: =_xlfn.XLOOKUP($L11,Mapping!$D$1:$D$11,Mapping!$B$1:$B$11) -> Activity | E11: =_xlfn.XLOOKUP($L11,Mapping!$D$1:$D$11,Mapping!$C$1:$C$11) -> Electrical | F11: Material Claiming | G11: =_xlfn.XLOOKUP(M11,Mapping!$S$1:$S$177,Mapping!$U$1:$U$177,"AUX") -> AUX | H11: 7383695 | I11: PACP-FDC-000687 | J11: =_xlfn.XLOOKUP(H11,Mapping!$F$1:$F$350,Mapping!$G$1:$G$350) -> 114239 | K11: 1 | L11: EA | M11: 4634903 | N11: =_xlfn.XLOOKUP(M11,Mapping!P:P,Mapping!Q:Q) -> CONN,C-TAP,CU,#6SOL-#4STR,#6SOL/STR,COMP | O11: 7383695 | P11: FDC Added | Q11: =_xlfn.XLOOKUP(M11,Mapping!$K$1:$K$223,Mapping!$M$1:$M$223,"SLM") -> SLM | T11: REM
A12: =_xlfn.XLOOKUP(B12,'Component ID-Name'!B:B,'Component ID-Name'!A:A,"") -> 10525986 | B12: =M12&"-"&O12 -> 6117709-7383695 | C12: =_xlfn.XLOOKUP(L12,Mapping!$D$1:$D$11,Mapping!$A$1:$A$11) -> 1116 | D12: =_xlfn.XLOOKUP($L12,Mapping!$D$1:$D$11,Mapping!$B$1:$B$11) -> Activity | E12: =_xlfn.XLOOKUP($L12,Mapping!$D$1:$D$11,Mapping!$C$1:$C$11) -> Electrical | F12: Material Claiming | G12: =_xlfn.XLOOKUP(M12,Mapping!$S$1:$S$177,Mapping!$U$1:$U$177,"AUX") -> AUX | H12: 7383695 | I12: PACP-FDC-000687 | J12: =_xlfn.XLOOKUP(H12,Mapping!$F$1:$F$350,Mapping!$G$1:$G$350) -> 114239 | K12: 1 | L12: EA | M12: 6117709 | N12: =_xlfn.XLOOKUP(M12,Mapping!P:P,Mapping!Q:Q) -> CONN,GRD,BRZ,XFMR,#8 SOL-#2 STR^ | O12: 7383695 | P12: FDC Added | Q12: =_xlfn.XLOOKUP(M12,Mapping!$K$1:$K$223,Mapping!$M$1:$M$223,"SLM") -> SLM | T12: REM
A13: =_xlfn.XLOOKUP(B13,'Component ID-Name'!B:B,'Component ID-Name'!A:A,"") -> 10525987 | B13: =M13&"-"&O13 -> 4626107-7383695 | C13: =_xlfn.XLOOKUP(L13,Mapping!$D$1:$D$11,Mapping!$A$1:$A$11) -> 1116 | D13: =_xlfn.XLOOKUP($L13,Mapping!$D$1:$D$11,Mapping!$B$1:$B$11) -> Activity | E13: =_xlfn.XLOOKUP($L13,Mapping!$D$1:$D$11,Mapping!$C$1:$C$11) -> Electrical | F13: Material Claiming | G13: =_xlfn.XLOOKUP(M13,Mapping!$S$1:$S$177,Mapping!$U$1:$U$177,"AUX") -> AUX | H13: 7383695 | I13: PACP-FDC-000687 | J13: =_xlfn.XLOOKUP(H13,Mapping!$F$1:$F$350,Mapping!$G$1:$G$350) -> 114239 | K13: 2 | L13: EA | M13: 4626107 | N13: =_xlfn.XLOOKUP(M13,Mapping!P:P,Mapping!Q:Q) -> CONN,H-TAP (#2),0.268-0.398,0.162-0.3 | O13: 7383695 | P13: FDC Added | Q13: =_xlfn.XLOOKUP(M13,Mapping!$K$1:$K$223,Mapping!$M$1:$M$223,"SLM") -> SLM | T13: REM
A14: =_xlfn.XLOOKUP(B14,'Component ID-Name'!B:B,'Component ID-Name'!A:A,"") -> 10525992 | B14: =M14&"-"&O14 -> 6279707-7383695 | C14: =_xlfn.XLOOKUP(L14,Mapping!$D$1:$D$11,Mapping!$A$1:$A$11) -> 1116 | D14: =_xlfn.XLOOKUP($L14,Mapping!$D$1:$D$11,Mapping!$B$1:$B$11) -> Activity | E14: =_xlfn.XLOOKUP($L14,Mapping!$D$1:$D$11,Mapping!$C$1:$C$11) -> Electrical | F14: Material Claiming | G14: =_xlfn.XLOOKUP(M14,Mapping!$S$1:$S$177,Mapping!$U$1:$U$177,"AUX") -> AUX | H14: 7383695 | I14: PACP-FDC-000687 | J14: =_xlfn.XLOOKUP(H14,Mapping!$F$1:$F$350,Mapping!$G$1:$G$350) -> 114239 | K14: 4 | L14: EA | M14: 6279707 | N14: =_xlfn.XLOOKUP(M14,Mapping!P:P,Mapping!Q:Q) -> WASHER,SPRING,5/8",DOUBLE HELIX | O14: 7383695 | P14: FDC Added | Q14: =_xlfn.XLOOKUP(M14,Mapping!$K$1:$K$223,Mapping!$M$1:$M$223,"SLM") -> SLM | T14: REM
A15: =_xlfn.XLOOKUP(B15,'Component ID-Name'!B:B,'Component ID-Name'!A:A,"") -> 10526002 | B15: =M15&"-"&O15 -> 8005123-7383695 | C15: =_xlfn.XLOOKUP(L15,Mapping!$D$1:$D$11,Mapping!$A$1:$A$11) -> 1116 | D15: =_xlfn.XLOOKUP($L15,Mapping!$D$1:$D$11,Mapping!$B$1:$B$11) -> Activity | E15: =_xlfn.XLOOKUP($L15,Mapping!$D$1:$D$11,Mapping!$C$1:$C$11) -> Electrical | F15: Material Claiming | G15: =_xlfn.XLOOKUP(M15,Mapping!$S$1:$S$177,Mapping!$U$1:$U$177,"AUX") -> AUX | H15: 7383695 | I15: PACP-FDC-000687 | J15: =_xlfn.XLOOKUP(H15,Mapping!$F$1:$F$350,Mapping!$G$1:$G$350) -> 114239 | K15: 1 | L15: EA | M15: 8005123 | N15: =_xlfn.XLOOKUP(M15,Mapping!P:P,Mapping!Q:Q) -> ARRESTER,SRG,NONEXPULSION,10KV,MOV | O15: 7383695 | P15: FDC Added | Q15: =_xlfn.XLOOKUP(M15,Mapping!$K$1:$K$223,Mapping!$M$1:$M$223,"SLM") -> SLM | T15: REM
A16: =_xlfn.XLOOKUP(B16,'Component ID-Name'!B:B,'Component ID-Name'!A:A,"") -> 10526014 | B16: =M16&"-"&O16 -> 6211106-7383695 | C16: =_xlfn.XLOOKUP(L16,Mapping!$D$1:$D$11,Mapping!$A$1:$A$11) -> 1116 | D16: =_xlfn.XLOOKUP($L16,Mapping!$D$1:$D$11,Mapping!$B$1:$B$11) -> Activity | E16: =_xlfn.XLOOKUP($L16,Mapping!$D$1:$D$11,Mapping!$C$1:$C$11) -> Electrical | F16: Material Claiming | G16: =_xlfn.XLOOKUP(M16,Mapping!$S$1:$S$177,Mapping!$U$1:$U$177,"AUX") -> AUX | H16: 7383695 | I16: PACP-FDC-000687 | J16: =_xlfn.XLOOKUP(H16,Mapping!$F$1:$F$350,Mapping!$G$1:$G$350) -> 114239 | K16: 4 | L16: EA | M16: 6211106 | N16: =_xlfn.XLOOKUP(M16,Mapping!P:P,Mapping!Q:Q) -> BOLT,MACH,5/8" X 12",XARM,GALV | O16: 7383695 | P16: FDC Added | Q16: =_xlfn.XLOOKUP(M16,Mapping!$K$1:$K$223,Mapping!$M$1:$M$223,"SLM") -> SLM | T16: REM
A17: =_xlfn.XLOOKUP(B17,'Component ID-Name'!B:B,'Component ID-Name'!A:A,"") -> 10526018 | B17: =M17&"-"&O17 -> 7991222-7383695 | C17: =_xlfn.XLOOKUP(L17,Mapping!$D$1:$D$11,Mapping!$A$1:$A$11) -> 1116 | D17: =_xlfn.XLOOKUP($L17,Mapping!$D$1:$D$11,Mapping!$B$1:$B$11) -> Activity | E17: =_xlfn.XLOOKUP($L17,Mapping!$D$1:$D$11,Mapping!$C$1:$C$11) -> Electrical | F17: Material Claiming | G17: =_xlfn.XLOOKUP(M17,Mapping!$S$1:$S$177,Mapping!$U$1:$U$177,"AUX") -> AUX | H17: 7383695 | I17: PACP-FDC-000687 | J17: =_xlfn.XLOOKUP(H17,Mapping!$F$1:$F$350,Mapping!$G$1:$G$350) -> 114239 | K17: 1 | L17: EA | M17: 7991222 | N17: =_xlfn.XLOOKUP(M17,Mapping!P:P,Mapping!Q:Q) -> BRACKET,FIBERGLASS,18",CUTOUT & ARRESTER | O17: 7383695 | P17: FDC Added | Q17: =_xlfn.XLOOKUP(M17,Mapping!$K$1:$K$223,Mapping!$M$1:$M$223,"SLM") -> SLM | T17: REM
A18: =_xlfn.XLOOKUP(B18,'Component ID-Name'!B:B,'Component ID-Name'!A:A,"") -> 10526020 | B18: =M18&"-"&O18 -> 1100065-7383695 | C18: =_xlfn.XLOOKUP(L18,Mapping!$D$1:$D$11,Mapping!$A$1:$A$11) -> 1007 | D18: =_xlfn.XLOOKUP($L18,Mapping!$D$1:$D$11,Mapping!$B$1:$B$11) -> Activity | E18: =_xlfn.XLOOKUP($L18,Mapping!$D$1:$D$11,Mapping!$C$1:$C$11) -> Electrical | F18: Material Claiming | G18: =_xlfn.XLOOKUP(M18,Mapping!$S$1:$S$177,Mapping!$U$1:$U$177,"AUX") -> AUX | H18: 7383695 | I18: PACP-FDC-000687 | J18: =_xlfn.XLOOKUP(H18,Mapping!$F$1:$F$350,Mapping!$G$1:$G$350) -> 114239 | K18: 21 | L18: FT | M18: 1100065 | N18: =_xlfn.XLOOKUP(M18,Mapping!P:P,Mapping!Q:Q) -> CABLE,UG,600V,#2,CU,SINGLE | O18: 7383695 | P18: FDC Added | Q18: =_xlfn.XLOOKUP(M18,Mapping!$K$1:$K$223,Mapping!$M$1:$M$223,"SLM") -> SLM | T18: REM
A19: =_xlfn.XLOOKUP(B19,'Component ID-Name'!B:B,'Component ID-Name'!A:A,"") -> 10526031 | B19: =M19&"-"&O19 -> 4601902-7383695 | C19: =_xlfn.XLOOKUP(L19,Mapping!$D$1:$D$11,Mapping!$A$1:$A$11) -> 1116 | D19: =_xlfn.XLOOKUP($L19,Mapping!$D$1:$D$11,Mapping!$B$1:$B$11) -> Activity | E19: =_xlfn.XLOOKUP($L19,Mapping!$D$1:$D$11,Mapping!$C$1:$C$11) -> Electrical | F19: Material Claiming | G19: =_xlfn.XLOOKUP(M19,Mapping!$S$1:$S$177,Mapping!$U$1:$U$177,"AUX") -> AUX | H19: 7383695 | I19: PACP-FDC-000687 | J19: =_xlfn.XLOOKUP(H19,Mapping!$F$1:$F$350,Mapping!$G$1:$G$350) -> 114239 | K19: 1 | L19: EA | M19: 4601902 | N19: =_xlfn.XLOOKUP(M19,Mapping!P:P,Mapping!Q:Q) -> CLAMP,HOTLINE,#8SOL-2/0STR,#8-2/0 CU | O19: 7383695 | P19: FDC Added | Q19: =_xlfn.XLOOKUP(M19,Mapping!$K$1:$K$223,Mapping!$M$1:$M$223,"SLM") -> SLM | T19: REM
A20: =_xlfn.XLOOKUP(B20,'Component ID-Name'!B:B,'Component ID-Name'!A:A,"") -> 10526059 | B20: =M20&"-"&O20 -> 1300812-7383695 | C20: =_xlfn.XLOOKUP(L20,Mapping!$D$1:$D$11,Mapping!$A$1:$A$11) -> 1116 | D20: =_xlfn.XLOOKUP($L20,Mapping!$D$1:$D$11,Mapping!$B$1:$B$11) -> Activity | E20: =_xlfn.XLOOKUP($L20,Mapping!$D$1:$D$11,Mapping!$C$1:$C$11) -> Electrical | F20: Material Claiming | G20: =_xlfn.XLOOKUP(M20,Mapping!$S$1:$S$177,Mapping!$U$1:$U$177,"AUX") -> AUX | H20: 7383695 | I20: PACP-FDC-000687 | J20: =_xlfn.XLOOKUP(H20,Mapping!$F$1:$F$350,Mapping!$G$1:$G$350) -> 114239 | K20: 1 | L20: EA | M20: 1300812 | N20: =_xlfn.XLOOKUP(M20,Mapping!P:P,Mapping!Q:Q) -> CONN,STIRRUP,BLTD,4-250AL/ACSR,1/0SOL | O20: 7383695 | P20: FDC Added | Q20: =_xlfn.XLOOKUP(M20,Mapping!$K$1:$K$223,Mapping!$M$1:$M$223,"SLM") -> SLM | T20: REM
A21: =_xlfn.XLOOKUP(B21,'Component ID-Name'!B:B,'Component ID-Name'!A:A,"") -> 10526078 | B21: =M21&"-"&O21 -> 8006321-7383695 | C21: =_xlfn.XLOOKUP(L21,Mapping!$D$1:$D$11,Mapping!$A$1:$A$11) -> 1116 | D21: =_xlfn.XLOOKUP($L21,Mapping!$D$1:$D$11,Mapping!$B$1:$B$11) -> Activity | E21: =_xlfn.XLOOKUP($L21,Mapping!$D$1:$D$11,Mapping!$C$1:$C$11) -> Electrical | F21: Material Claiming | G21: =_xlfn.XLOOKUP(M21,Mapping!$S$1:$S$177,Mapping!$U$1:$U$177,"AUX") -> AUX | H21: 7383695 | I21: PACP-FDC-000687 | J21: =_xlfn.XLOOKUP(H21,Mapping!$F$1:$F$350,Mapping!$G$1:$G$350) -> 114239 | K21: 1 | L21: EA | M21: 8006321 | N21: =_xlfn.XLOOKUP(M21,Mapping!P:P,Mapping!Q:Q) -> COVER,CUTOUT,FR RATED,POLYMER,27KV150BIL | O21: 7383695 | P21: FDC Added | Q21: =_xlfn.XLOOKUP(M21,Mapping!$K$1:$K$223,Mapping!$M$1:$M$223,"SLM") -> SLM | T21: REM
A22: =_xlfn.XLOOKUP(B22,'Component ID-Name'!B:B,'Component ID-Name'!A:A,"") -> 10526058 | B22: =M22&"-"&O22 -> 8006513-7383695 | C22: =_xlfn.XLOOKUP(L22,Mapping!$D$1:$D$11,Mapping!$A$1:$A$11) -> 1116 | D22: =_xlfn.XLOOKUP($L22,Mapping!$D$1:$D$11,Mapping!$B$1:$B$11) -> Activity | E22: =_xlfn.XLOOKUP($L22,Mapping!$D$1:$D$11,Mapping!$C$1:$C$11) -> Electrical | F22: Material Claiming | G22: =_xlfn.XLOOKUP(M22,Mapping!$S$1:$S$177,Mapping!$U$1:$U$177,"AUX") -> AUX | H22: 7383695 | I22: PACP-FDC-000687 | J22: =_xlfn.XLOOKUP(H22,Mapping!$F$1:$F$350,Mapping!$G$1:$G$350) -> 114239 | K22: 1 | L22: EA | M22: 8006513 | N22: =_xlfn.XLOOKUP(M22,Mapping!P:P,Mapping!Q:Q) -> COVER,STIRRUP,COVERED CONDUCTOR^ | O22: 7383695 | P22: FDC Added | Q22: =_xlfn.XLOOKUP(M22,Mapping!$K$1:$K$223,Mapping!$M$1:$M$223,"SLM") -> SLM | T22: REM
... A61: =_xlfn.XLOOKUP(B61,'Component ID-Name'!B:B,'Component ID-Name'!A:A,"") -> 10526120 | B61: =M61&"-"&O61 -> 7992709-7383695 | C61: =_xlfn.XLOOKUP(L61,Mapping!$D$1:$D$11,Mapping!$A$1:$A$11) -> 1116 | D61: =_xlfn.XLOOKUP($L61,Mapping!$D$1:$D$11,Mapping!$B$1:$B$11) -> Activity | E61: =_xlfn.XLOOKUP($L61,Mapping!$D$1:$D$11,Mapping!$C$1:$C$11) -> Electrical | F61: Material Claiming | G61: =_xlfn.XLOOKUP(M61,Mapping!$S$1:$S$177,Mapping!$U$1:$U$177,"AUX") -> AUX | H61: 7383695 | I61: PACP-FDC-000698 | J61: =_xlfn.XLOOKUP(H61,Mapping!$F$1:$F$350,Mapping!$G$1:$G$350) -> 114239 | K61: 1 | L61: EA | M61: 7992709 | N61: =_xlfn.XLOOKUP(M61,Mapping!P:P,Mapping!Q:Q) -> XARM,FIBERGLASS,DEADEND,10FT,2POSITION^ | O61: 7383695 | P61: FDC Added | Q61: =_xlfn.XLOOKUP(M61,Mapping!$K$1:$K$223,Mapping!$M$1:$M$223,"SLM") -> SLM | T61: REM
A62: =_xlfn.XLOOKUP(B62,'Component ID-Name'!B:B,'Component ID-Name'!A:A,"") | B62: =M62&"-"&O62 -> - | C62: =_xlfn.XLOOKUP(L62,Mapping!$D$1:$D$11,Mapping!$A$1:$A$11) -> #N/A | D62: =_xlfn.XLOOKUP($L62,Mapping!$D$1:$D$11,Mapping!$B$1:$B$11) -> #N/A | E62: =_xlfn.XLOOKUP($L62,Mapping!$D$1:$D$11,Mapping!$C$1:$C$11) -> #N/A | F62: Material Claiming | G62: =_xlfn.XLOOKUP(M62,Mapping!$S$1:$S$177,Mapping!$U$1:$U$177,"AUX") -> 0 | J62: =_xlfn.XLOOKUP(H62,Mapping!$F$1:$F$350,Mapping!$G$1:$G$350) -> 0 | N62: =_xlfn.XLOOKUP(M62,Mapping!P:P,Mapping!Q:Q) -> 0 | Q62: =_xlfn.XLOOKUP(M62,Mapping!$K$1:$K$223,Mapping!$M$1:$M$223,"SLM") -> SLM | T62: REM
A63: =_xlfn.XLOOKUP(B63,'Component ID-Name'!B:B,'Component ID-Name'!A:A,"") | B63: =M63&"-"&O63 -> - | C63: =_xlfn.XLOOKUP(L63,Mapping!$D$1:$D$11,Mapping!$A$1:$A$11) -> #N/A | D63: =_xlfn.XLOOKUP($L63,Mapping!$D$1:$D$11,Mapping!$B$1:$B$11) -> #N/A | E63: =_xlfn.XLOOKUP($L63,Mapping!$D$1:$D$11,Mapping!$C$1:$C$11) -> #N/A | F63: Material Claiming | G63: =_xlfn.XLOOKUP(M63,Mapping!$S$1:$S$177,Mapping!$U$1:$U$177,"AUX") -> 0 | J63: =_xlfn.XLOOKUP(H63,Mapping!$F$1:$F$350,Mapping!$G$1:$G$350) -> 0 | N63: =_xlfn.XLOOKUP(M63,Mapping!P:P,Mapping!Q:Q) -> 0 | Q63: =_xlfn.XLOOKUP(M63,Mapping!$K$1:$K$223,Mapping!$M$1:$M$223,"SLM") -> SLM | T63: REM
A64: =_xlfn.XLOOKUP(B64,'Component ID-Name'!B:B,'Component ID-Name'!A:A,"") | B64: =M64&"-"&O64 -> - | C64: =_xlfn.XLOOKUP(L64,Mapping!$D$1:$D$11,Mapping!$A$1:$A$11) -> #N/A | D64: =_xlfn.XLOOKUP($L64,Mapping!$D$1:$D$11,Mapping!$B$1:$B$11) -> #N/A | E64: =_xlfn.XLOOKUP($L64,Mapping!$D$1:$D$11,Mapping!$C$1:$C$11) -> #N/A | F64: Material Claiming | G64: =_xlfn.XLOOKUP(M64,Mapping!$S$1:$S$177,Mapping!$U$1:$U$177,"AUX") -> 0 | J64: =_xlfn.XLOOKUP(H64,Mapping!$F$1:$F$350,Mapping!$G$1:$G$350) -> 0 | N64: =_xlfn.XLOOKUP(M64,Mapping!P:P,Mapping!Q:Q) -> 0 | Q64: =_xlfn.XLOOKUP(M64,Mapping!$K$1:$K$223,Mapping!$M$1:$M$223,"SLM") -> SLM | T64: REM
A65: =_xlfn.XLOOKUP(B65,'Component ID-Name'!B:B,'Component ID-Name'!A:A,"") | B65: =M65&"-"&O65 -> - | C65: =_xlfn.XLOOKUP(L65,Mapping!$D$1:$D$11,Mapping!$A$1:$A$11) -> #N/A | D65: =_xlfn.XLOOKUP($L65,Mapping!$D$1:$D$11,Mapping!$B$1:$B$11) -> #N/A | E65: =_xlfn.XLOOKUP($L65,Mapping!$D$1:$D$11,Mapping!$C$1:$C$11) -> #N/A | F65: Material Claiming | G65: =_xlfn.XLOOKUP(M65,Mapping!$S$1:$S$177,Mapping!$U$1:$U$177,"AUX") -> 0 | J65: =_xlfn.XLOOKUP(H65,Mapping!$F$1:$F$350,Mapping!$G$1:$G$350) -> 0 | N65: =_xlfn.XLOOKUP(M65,Mapping!P:P,Mapping!Q:Q) -> 0 | Q65: =_xlfn.XLOOKUP(M65,Mapping!$K$1:$K$223,Mapping!$M$1:$M$223,"SLM") -> SLM | T65: REM
A66: =_xlfn.XLOOKUP(B66,'Component ID-Name'!B:B,'Component ID-Name'!A:A,"") | B66: =M66&"-"&O66 -> - | C66: =_xlfn.XLOOKUP(L66,Mapping!$D$1:$D$11,Mapping!$A$1:$A$11) -> #N/A | D66: =_xlfn.XLOOKUP($L66,Mapping!$D$1:$D$11,Mapping!$B$1:$B$11) -> #N/A | E66: =_xlfn.XLOOKUP($L66,Mapping!$D$1:$D$11,Mapping!$C$1:$C$11) -> #N/A | F66: Material Claiming | G66: =_xlfn.XLOOKUP(M66,Mapping!$S$1:$S$177,Mapping!$U$1:$U$177,"AUX") -> 0 | J66: =_xlfn.XLOOKUP(H66,Mapping!$F$1:$F$350,Mapping!$G$1:$G$350) -> 0 | N66: =_xlfn.XLOOKUP(M66,Mapping!P:P,Mapping!Q:Q) -> 0 | Q66: =_xlfn.XLOOKUP(M66,Mapping!$K$1:$K$223,Mapping!$M$1:$M$223,"SLM") -> SLM | T66: REM
A67: =_xlfn.XLOOKUP(B67,'Component ID-Name'!B:B,'Component ID-Name'!A:A,"") | B67: =M67&"-"&O67 -> - | C67: =_xlfn.XLOOKUP(L67,Mapping!$D$1:$D$11,Mapping!$A$1:$A$11) -> #N/A | D67: =_xlfn.XLOOKUP($L67,Mapping!$D$1:$D$11,Mapping!$B$1:$B$11) -> #N/A | E67: =_xlfn.XLOOKUP($L67,Mapping!$D$1:$D$11,Mapping!$C$1:$C$11) -> #N/A | F67: Material Claiming | G67: =_xlfn.XLOOKUP(M67,Mapping!$S$1:$S$177,Mapping!$U$1:$U$177,"AUX") -> 0 | J67: =_xlfn.XLOOKUP(H67,Mapping!$F$1:$F$350,Mapping!$G$1:$G$350) -> 0 | N67: =_xlfn.XLOOKUP(M67,Mapping!P:P,Mapping!Q:Q) -> 0 | Q67: =_xlfn.XLOOKUP(M67,Mapping!$K$1:$K$223,Mapping!$M$1:$M$223,"SLM") -> SLM | T67: REM
A68: =_xlfn.XLOOKUP(B68,'Component ID-Name'!B:B,'Component ID-Name'!A:A,"") | B68: =M68&"-"&O68 -> - | C68: =_xlfn.XLOOKUP(L68,Mapping!$D$1:$D$11,Mapping!$A$1:$A$11) -> #N/A | D68: =_xlfn.XLOOKUP($L68,Mapping!$D$1:$D$11,Mapping!$B$1:$B$11) -> #N/A | E68: =_xlfn.XLOOKUP($L68,Mapping!$D$1:$D$11,Mapping!$C$1:$C$11) -> #N/A | F68: Material Claiming | G68: =_xlfn.XLOOKUP(M68,Mapping!$S$1:$S$177,Mapping!$U$1:$U$177,"AUX") -> 0 | J68: =_xlfn.XLOOKUP(H68,Mapping!$F$1:$F$350,Mapping!$G$1:$G$350) -> 0 | N68: =_xlfn.XLOOKUP(M68,Mapping!P:P,Mapping!Q:Q) -> 0 | Q68: =_xlfn.XLOOKUP(M68,Mapping!$K$1:$K$223,Mapping!$M$1:$M$223,"SLM") -> SLM | T68: REM
A69: =_xlfn.XLOOKUP(B69,'Component ID-Name'!B:B,'Component ID-Name'!A:A,"") | B69: =M69&"-"&O69 -> - | C69: =_xlfn.XLOOKUP(L69,Mapping!$D$1:$D$11,Mapping!$A$1:$A$11) -> #N/A | D69: =_xlfn.XLOOKUP($L69,Mapping!$D$1:$D$11,Mapping!$B$1:$B$11) -> #N/A | E69: =_xlfn.XLOOKUP($L69,Mapping!$D$1:$D$11,Mapping!$C$1:$C$11) -> #N/A | F69: Material Claiming | G69: =_xlfn.XLOOKUP(M69,Mapping!$S$1:$S$177,Mapping!$U$1:$U$177,"AUX") -> 0 | J69: =_xlfn.XLOOKUP(H69,Mapping!$F$1:$F$350,Mapping!$G$1:$G$350) -> 0 | N69: =_xlfn.XLOOKUP(M69,Mapping!P:P,Mapping!Q:Q) -> 0 | Q69: =_xlfn.XLOOKUP(M69,Mapping!$K$1:$K$223,Mapping!$M$1:$M$223,"SLM") -> SLM | T69: REM
A70: =_xlfn.XLOOKUP(B70,'Component ID-Name'!B:B,'Component ID-Name'!A:A,"") | B70: =M70&"-"&O70 -> - | C70: =_xlfn.XLOOKUP(L70,Mapping!$D$1:$D$11,Mapping!$A$1:$A$11) -> #N/A | D70: =_xlfn.XLOOKUP($L70,Mapping!$D$1:$D$11,Mapping!$B$1:$B$11) -> #N/A | E70: =_xlfn.XLOOKUP($L70,Mapping!$D$1:$D$11,Mapping!$C$1:$C$11) -> #N/A | F70: Material Claiming | G70: =_xlfn.XLOOKUP(M70,Mapping!$S$1:$S$177,Mapping!$U$1:$U$177,"AUX") -> 0 | J70: =_xlfn.XLOOKUP(H70,Mapping!$F$1:$F$350,Mapping!$G$1:$G$350) -> 0 | N70: =_xlfn.XLOOKUP(M70,Mapping!P:P,Mapping!Q:Q) -> 0 | Q70: =_xlfn.XLOOKUP(M70,Mapping!$K$1:$K$223,Mapping!$M$1:$M$223,"SLM") -> SLM | T70: REM
A71: =_xlfn.XLOOKUP(B71,'Component ID-Name'!B:B,'Component ID-Name'!A:A,"") | B71: =M71&"-"&O71 -> - | C71: =_xlfn.XLOOKUP(L71,Mapping!$D$1:$D$11,Mapping!$A$1:$A$11) -> #N/A | D71: =_xlfn.XLOOKUP($L71,Mapping!$D$1:$D$11,Mapping!$B$1:$B$11) -> #N/A | E71: =_xlfn.XLOOKUP($L71,Mapping!$D$1:$D$11,Mapping!$C$1:$C$11) -> #N/A | F71: Material Claiming | G71: =_xlfn.XLOOKUP(M71,Mapping!$S$1:$S$177,Mapping!$U$1:$U$177,"AUX") -> 0 | J71: =_xlfn.XLOOKUP(H71,Mapping!$F$1:$F$350,Mapping!$G$1:$G$350) -> 0 | N71: =_xlfn.XLOOKUP(M71,Mapping!P:P,Mapping!Q:Q) -> 0 | Q71: =_xlfn.XLOOKUP(M71,Mapping!$K$1:$K$223,Mapping!$M$1:$M$223,"SLM") -> SLM | T71: REM
A72: =_xlfn.XLOOKUP(B72,'Component ID-Name'!B:B,'Component ID-Name'!A:A,"") | B72: =M72&"-"&O72 -> - | C72: =_xlfn.XLOOKUP(L72,Mapping!$D$1:$D$11,Mapping!$A$1:$A$11) -> #N/A | D72: =_xlfn.XLOOKUP($L72,Mapping!$D$1:$D$11,Mapping!$B$1:$B$11) -> #N/A | E72: =_xlfn.XLOOKUP($L72,Mapping!$D$1:$D$11,Mapping!$C$1:$C$11) -> #N/A | F72: Material Claiming | G72: =_xlfn.XLOOKUP(M72,Mapping!$S$1:$S$177,Mapping!$U$1:$U$177,"AUX") -> 0 | J72: =_xlfn.XLOOKUP(H72,Mapping!$F$1:$F$350,Mapping!$G$1:$G$350) -> 0 | N72: =_xlfn.XLOOKUP(M72,Mapping!P:P,Mapping!Q:Q) -> 0 | Q72: =_xlfn.XLOOKUP(M72,Mapping!$K$1:$K$223,Mapping!$M$1:$M$223,"SLM") -> SLM | T72: REM
A73: =_xlfn.XLOOKUP(B73,'Component ID-Name'!B:B,'Component ID-Name'!A:A,"") | B73: =M73&"-"&O73 -> - | C73: =_xlfn.XLOOKUP(L73,Mapping!$D$1:$D$11,Mapping!$A$1:$A$11) -> #N/A | D73: =_xlfn.XLOOKUP($L73,Mapping!$D$1:$D$11,Mapping!$B$1:$B$11) -> #N/A | E73: =_xlfn.XLOOKUP($L73,Mapping!$D$1:$D$11,Mapping!$C$1:$C$11) -> #N/A | F73: Material Claiming | G73: =_xlfn.XLOOKUP(M73,Mapping!$S$1:$S$177,Mapping!$U$1:$U$177,"AUX") -> 0 | J73: =_xlfn.XLOOKUP(H73,Mapping!$F$1:$F$350,Mapping!$G$1:$G$350) -> 0 | N73: =_xlfn.XLOOKUP(M73,Mapping!P:P,Mapping!Q:Q) -> 0 | Q73: =_xlfn.XLOOKUP(M73,Mapping!$K$1:$K$223,Mapping!$M$1:$M$223,"SLM") -> SLM | T73: REM
... A1334: =_xlfn.XLOOKUP(B1334,'Component ID-Name'!B:B,'Component ID-Name'!A:A,"") | B1334: =M1334&"-"&O1334 -> - | C1334: =_xlfn.XLOOKUP(L1334,Mapping!$D$1:$D$11,Mapping!$A$1:$A$11) -> #N/A | D1334: =_xlfn.XLOOKUP($L1334,Mapping!$D$1:$D$11,Mapping!$B$1:$B$11) -> #N/A | E1334: =_xlfn.XLOOKUP($L1334,Mapping!$D$1:$D$11,Mapping!$C$1:$C$11) -> #N/A | F1334: Material Claiming | G1334: =_xlfn.XLOOKUP(M1334,Mapping!$S$1:$S$177,Mapping!$U$1:$U$177,"AUX") -> 0 | J1334: =_xlfn.XLOOKUP(H1334,Mapping!$F$1:$F$350,Mapping!$G$1:$G$350) -> 0 | N1334: =_xlfn.XLOOKUP(M1334,Mapping!P:P,Mapping!Q:Q) -> 0 | Q1334: =_xlfn.XLOOKUP(M1334,Mapping!$K$1:$K$223,Mapping!$M$1:$M$223,"SLM") -> SLM | T1334: REM
A1335: =_xlfn.XLOOKUP(B1335,'Component ID-Name'!B:B,'Component ID-Name'!A:A,"") | B1335: =M1335&"-"&O1335 -> - | C1335: =_xlfn.XLOOKUP(L1335,Mapping!$D$1:$D$11,Mapping!$A$1:$A$11) -> #N/A | D1335: =_xlfn.XLOOKUP($L1335,Mapping!$D$1:$D$11,Mapping!$B$1:$B$11) -> #N/A | E1335: =_xlfn.XLOOKUP($L1335,Mapping!$D$1:$D$11,Mapping!$C$1:$C$11) -> #N/A | F1335: Material Claiming | G1335: =_xlfn.XLOOKUP(M1335,Mapping!$S$1:$S$177,Mapping!$U$1:$U$177,"AUX") -> 0 | J1335: =_xlfn.XLOOKUP(H1335,Mapping!$F$1:$F$175,Mapping!$G$1:$G$175) -> #N/A | N1335: =_xlfn.XLOOKUP(M1335,Mapping!P:P,Mapping!Q:Q) -> 0 | Q1335: =_xlfn.XLOOKUP(M1335,Mapping!$K$1:$K$223,Mapping!$M$1:$M$223,"SLM") -> SLM | T1335: REM
A1336: =_xlfn.XLOOKUP(B1336,'Component ID-Name'!B:B,'Component ID-Name'!A:A,"") | B1336: =M1336&"-"&O1336 -> - | C1336: =_xlfn.XLOOKUP(L1336,Mapping!$D$1:$D$11,Mapping!$A$1:$A$11) -> #N/A | D1336: =_xlfn.XLOOKUP($L1336,Mapping!$D$1:$D$11,Mapping!$B$1:$B$11) -> #N/A | E1336: =_xlfn.XLOOKUP($L1336,Mapping!$D$1:$D$11,Mapping!$C$1:$C$11) -> #N/A | F1336: Material Claiming | G1336: =_xlfn.XLOOKUP(M1336,Mapping!$S$1:$S$177,Mapping!$U$1:$U$177,"AUX") -> 0 | J1336: =_xlfn.XLOOKUP(H1336,Mapping!$F$1:$F$175,Mapping!$G$1:$G$175) -> #N/A | N1336: =_xlfn.XLOOKUP(M1336,Mapping!P:P,Mapping!Q:Q) -> 0 | Q1336: =_xlfn.XLOOKUP(M1336,Mapping!$K$1:$K$223,Mapping!$M$1:$M$223,"SLM") -> SLM | T1336: REM
A1337: =_xlfn.XLOOKUP(B1337,'Component ID-Name'!B:B,'Component ID-Name'!A:A,"") | B1337: =M1337&"-"&O1337 -> - | C1337: =_xlfn.XLOOKUP(L1337,Mapping!$D$1:$D$11,Mapping!$A$1:$A$11) -> #N/A | D1337: =_xlfn.XLOOKUP($L1337,Mapping!$D$1:$D$11,Mapping!$B$1:$B$11) -> #N/A | E1337: =_xlfn.XLOOKUP($L1337,Mapping!$D$1:$D$11,Mapping!$C$1:$C$11) -> #N/A | F1337: Material Claiming | G1337: =_xlfn.XLOOKUP(M1337,Mapping!$S$1:$S$177,Mapping!$U$1:$U$177,"AUX") -> 0 | J1337: =_xlfn.XLOOKUP(H1337,Mapping!$F$1:$F$175,Mapping!$G$1:$G$175) -> #N/A | N1337: =_xlfn.XLOOKUP(M1337,Mapping!P:P,Mapping!Q:Q) -> 0 | Q1337: =_xlfn.XLOOKUP(M1337,Mapping!$K$1:$K$223,Mapping!$M$1:$M$223,"SLM") -> SLM | T1337: REM
A1338: =_xlfn.XLOOKUP(B1338,'Component ID-Name'!B:B,'Component ID-Name'!A:A,"") | B1338: =M1338&"-"&O1338 -> - | C1338: =_xlfn.XLOOKUP(L1338,Mapping!$D$1:$D$11,Mapping!$A$1:$A$11) -> #N/A | D1338: =_xlfn.XLOOKUP($L1338,Mapping!$D$1:$D$11,Mapping!$B$1:$B$11) -> #N/A | E1338: =_xlfn.XLOOKUP($L1338,Mapping!$D$1:$D$11,Mapping!$C$1:$C$11) -> #N/A | F1338: Material Claiming | G1338: =_xlfn.XLOOKUP(M1338,Mapping!$S$1:$S$177,Mapping!$U$1:$U$177,"AUX") -> 0 | J1338: =_xlfn.XLOOKUP(H1338,Mapping!$F$1:$F$175,Mapping!$G$1:$G$175) -> #N/A | N1338: =_xlfn.XLOOKUP(M1338,Mapping!P:P,Mapping!Q:Q) -> 0 | Q1338: =_xlfn.XLOOKUP(M1338,Mapping!$K$1:$K$223,Mapping!$M$1:$M$223,"SLM") -> SLM | T1338: REM
...

Sheet Discipline or Commodity specifi
A1: Type | B1: Discipline/Commodity | C1: Discipline/Commodity specific attribute
A2: Discipline | B2: Aggregates and Paving | C2: Account Code Description
A3: Discipline | B3: Aggregates and Paving | C3: Account Code Number
A4: Discipline | B4: Aggregates and Paving | C4: Actual Quantity
A5: Discipline | B5: Aggregates and Paving | C5: Asphalt Design
A6: Discipline | B6: Aggregates and Paving | C6: Asphalt Mix
A7: Discipline | B7: Aggregates and Paving | C7: AUX 1
A8: Discipline | B8: Aggregates and Paving | C8: AUX 2
A9: Discipline | B9: Aggregates and Paving | C9: AUX 3
A10: Discipline | B10: Aggregates and Paving | C10: AUX 4
A11: Discipline | B11: Aggregates and Paving | C11: AUX 5
A12: Discipline | B12: Aggregates and Paving | C12: AUX 6
... A1632: Commodity | B1632: Valves | C1632: Tag Type

Sheet Component ID-Name
A1: Component Id | B1: Name
A2: Numeric | B2: Text
B3: 200
A4: 10961938 | B4: 0652248-7345566
A5: 10337388 | B5: 1000957-7367010
A6: 10337383 | B6: 1000958-7367010
A7: 10432983 | B7: 1001592-7011443
A8: 10328136 | B8: 1001592-7011445
A9: 10435899 | B9: 1001592-7061259
A10: 10336024 | B10: 1001592-7142247
A11: 10437515 | B11: 1001592-7153574
A12: 10338561 | B12: 1001592-7153749
A13: 10332428 | B13: 1001592-7159921
A14: 10436385 | B14: 1001592-7195720
A15: 10778605 | B15: 1001592-7195726
... A34017: 10339776 | B34017: VACSWITCH-7335354

Sheet Datasource

Sheet Mapping
A1: WBS | B1: Type | C1: Discipline/Commodity | D1: UofM | F1: WO # | G1: Workpackage ID | K1: SN | L1: Desciption | M1: PO | P1: S/N | Q1: Description | S1: SN | T1: Desciption | U1: PO
A2: 1116 | B2: Activity | C2: Electrical | D2: EA | F2: 7548745 | G2: 127748 | K2: 1008000 | L2: POLE, STEEL, 40FT, CLASS 2, DISTRIBUTION | M2: Bulk | P2: 1000957 | Q2: LUBE,PULLING,CABLE,WINTER GRADE,1 GALLON | S2: 1008000 | T2: POLE, STEEL, 40FT, CLASS 2, DISTRIBUTION | U2: STR
A3: 1007 | B3: Activity | C3: Electrical | D3: FT | F3: 7431863 | G3: 127747 | K3: 8006412 | L3: POLE, STEEL, 45FT, CLASS 1, DISTRIBUTION | M3: Bulk | P3: 1000958 | Q3: LUBE,PULLING,CBL,WINTER WEATHER,5 GAL | S3: 8006412 | T3: POLE, STEEL, 45FT, CLASS 1, DISTRIBUTION | U3: STR
A4: 1009 | B4: Activity | C4: Electrical | D4: KAN | F4: 7427596 | G4: 127746 | K4: 8006413 | L4: POLE, STEEL, 50FT, CLASS 1, DISTRIBUTION | M4: Bulk | P4: 1001592 | Q4: ANCHOR ASSY,24" X 5/16" DISK,1" X 10' ROD | S4: 8006413 | T4: POLE, STEEL, 50FT, CLASS 1, DISTRIBUTION | U4: STR
A5: 1010 | B5: Activity | C5: Electrical | D5: LB | F5: 7427592 | G5: 127745 | K5: 1008009 | L5: POLE, STEEL, 55FT, CLASS 1, DISTRIBUTION | M5: Bulk | P5: 1001594 | Q5: ANCHOR ASSEMBLY,30" DISK ANCHOR | S5: 1008009 | T5: POLE, STEEL, 55FT, CLASS 1, DISTRIBUTION | U5: STR
A6: 1044 | B6: Activity | C6: Electrical | D6: PAA | F6: 7427312 | G6: 127744 | K6: 1008012 | L6: POLE, STEEL, 60FT, CLASS 1, DISTRIBUTION | M6: Bulk | P6: 1001998 | Q6: LINK,CLEVIS,EYE,15"C-C,NAR THRT,13/16"EY | S6: 1008012 | T6: POLE, STEEL, 60FT, CLASS 1, DISTRIBUTION | U6: STR
A7: 1045 | B7: Activity | C7: Electrical | D7: PT | F7: 7358178 | G7: 127743 | K7: 4504908 | L7: CONDUCTOR, AAC, 4/0, 7STR, OXLIP | M7: Bulk | P7: 1002438 | Q7: BRACKET,MTG,UG,TERM,0.75" - 3" | S7: 4504908 | T7: CONDUCTOR, AAC, 4/0, 7STR, OXLIP | U7: PDC
A8: 1046 | B8: Activity | C8: Electrical | D8: Reel | F8: 7310724 | G8: 127742 | K8: 4505077 | L8: CONDUCTOR, AAC, 477KCMIL, 19STR, COSMOS | M8: Bulk | P8: 1002715 | Q8: SUSPENSION ASSY,WIRE,1/2"EHS,FORMED GRIP | S8: 4505077 | T8: CONDUCTOR, AAC, 477KCMIL, 19STR, COSMOS | U8: PDC
A9: 1047 | B9: Activity | C9: Electrical | D9: YD | F9: 7295737 | G9: 127741 | K9: 4508701 | L9: CONDUCTOR, ACSR, 1/0, 6/1STR, RAVEN | M9: Bulk | P9: 1002760 | Q9: CONN,MINIWG,1/0AAAC/ACSR/AAC/CU STR-#4 | S9: 4508701 | T9: CONDUCTOR, ACSR, 1/0, 6/1STR, RAVEN | U9: PDC
A10: 1008 | B10: Activity | C10: Electrical | D10: HR | F10: 7291793 | G10: 127265 | K10: 4509006 | L10: CONDUCTOR, ACSR, 4/0, 6/1STR, PENGUIN, 36" | M10: Bulk | P10: 1002762 | Q10: CONN,MINIWG,1/0AAAC/ACSR/AAC/CU STR-1/0 | S10: 4509006 | T10: CONDUCTOR, ACSR, 4/0, 6/1STR, PENGUIN, 36" | U10: PDC
A11: 1043 | B11: Activity | C11: Electrical | D11: LF | F11: 8231407 | G11: 126743 | K11: 8006173 | L11: CONDUCTOR, TREE WIRE, 1/0 ACSR, 15KV, GRY | M11: Bulk | P11: 1002768 | Q11: CONN,MINIWG,4/0AAAC/ACSR/AAC/CU STR-2/0 | S11: 8006173 | T11: CONDUCTOR, TREE WIRE, 1/0 ACSR, 15KV, GRY | U11: PDC
F12: 8231406 | G12: 126742 | K12: 8006174 | L12: CONDUCTOR, TREE WIRE, 4/0 ACSR, 15KV, GRY | M12: Bulk | P12: 1002799 | Q12: CLIP,BONDING,1/2" BOLT | S12: 8006174 | T12: CONDUCTOR, TREE WIRE, 4/0 ACSR, 15KV, GRY | U12: PDC
F13: 8222499 | G13: 126741 | K13: 8006175 | L13: CONDUCTOR, TREE WIRE, 477ACSR, 15KV, GRY | M13: Bulk | P13: 1002800 | Q13: CLIP,BONDING,5/8" BOLT | S13: 8006175 | T13: CONDUCTOR, TREE WIRE, 477ACSR, 15KV, GRY | U13: PDC
F14: 8206187 | G14: 126740 | K14: 8006177 | L14: CONDUCTOR, TREE WIRE, 795 ACSR, 15KV, GRY | M14: Bulk | P14: 1002801 | Q14: CLIP,BONDING,3/4" BOLT | S14: 8006177 | T14: CONDUCTOR, TREE WIRE, 795 ACSR, 15KV, GRY | U14: PDC
F15: 8077847 | G15: 126739 | K15: 8006178 | L15: CONDUCTOR,TREE WIRE,1/0 ACSR,25KV,GRAY^ | M15: Bulk | P15: 1002802 | Q15: CLIP,BONDING,7/8" BOLT | S15: 8006178 | T15: CONDUCTOR,TREE WIRE,1/0 ACSR,25KV,GRAY^ | U15: PDC
F16: 8077848 | G16: 126738 | K16: 8006179 | L16: CONDUCTOR,TREE WIRE,4/0 ACSR,25KV,GRAY^ | M16: Bulk | P16: 1002803 | Q16: CLIP,BONDING,1" BOLT | S16: 8006179 | T16: CONDUCTOR,TREE WIRE,4/0 ACSR,25KV,GRAY^ | U16: PDC
F17: 7489643 | G17: 126737 | K17: 8006180 | L17: CONDUCTOR,TREE WIRE,477 ACSR,25KV,GRAY^ | M17: Bulk | P17: 1002806 | Q17: CLAMP,SUSP,AL,0.40"-0.86",W/H.L.SKTEYE15 | S17: 8006180 | T17: CONDUCTOR,TREE WIRE,477 ACSR,25KV,GRAY^ | U17: PDC
F18: 7460179 | G18: 126736 | K18: 7999063 | L18: POLE,STEEL,60 FT,WEATHERING,UNGUYED ANGL | M18: LLM | P18: 1002807 | Q18: CLAMP,SUSP,AL,0.50"-1.00",W/H.L.SKTEYE15 | S18: 7999063 | T18: POLE,STEEL,60 FT,WEATHERING,UNGUYED ANGL | U18: STR
F19: 7444059 | G19: 126735 | K19: 7991952 | L19: POLE,STEEL,55,DE,SELF-SUPRT,DB,1820FT-K^ | M19: LLM | P19: 1002809 | Q19: CLAMP,SUSP,AL,0.90"-1.39",W/H.L.SKTEYE15 | S19: 7991952 | T19: POLE,STEEL,55,DE,SELF-SUPRT,DB,1820FT-K^ | U19: STR
F20: 7437332 | G20: 126734 | K20: 8005893 | L20: CONDUCTOR, COVERED, SPACER, 1/0, 15KV, GRY | M20: LLM | P20: 1002821 | Q20: LINK,CLEVIS,EYE,15"C-C,WIDE THRT,13/16"E | S20: 8005893 | T20: CONDUCTOR, COVERED, SPACER, 1/0, 15KV, GRY | U20: PDC
F21: 7432041 | G21: 126733 | K21: 8005894 | L21: CONDUCTOR, COVERED, SPACER, 4/0, 15KV, GRY | M21: LLM | P21: 1002824 | Q21: INSUL,STRAIN,FBRGL,252",CLEVIS,W/ROLL,2 | S21: 8005894 | T21: CONDUCTOR, COVERED, SPACER, 4/0, 15KV, GRY | U21: PDC
F22: 7427594 | G22: 126732 | K22: 8005895 | L22: CONDUCTOR,COVERED,SPACER, 477, 15 KV,GRY | M22: LLM | P22: 1002825 | Q22: INSUL,STRAIN,FBRGL,119.5",DOUBLE ROLLER | S22: 8005895 | T22: CONDUCTOR,COVERED,SPACER, 477, 15 KV,GRY | U22: PDC
F23: 7427589 | G23: 126731 | K23: 8005896 | L23: CONDUCTOR,COVERED,SPACER, 795, 15 KV,GRY | M23: LLM | P23: 1002836 | Q23: CLAMP,DE,STRAIN,QUAD,0.30"-0.84",GALV | S23: 8005896 | T23: CONDUCTOR,COVERED,SPACER, 795, 15 KV,GRY | U23: PDC
... F176: 7397577 | G176: 114404 | K176: 7991669 | L176: POLE, STEEL, 90FT, CLASS EH8 | M176: LLM | P176: 1580277 | Q176: SHACKLE,HOLD DN,5-1/16"L,2-7/8"OPN,5/8"^ | S176: 7999194 | T176: CONDUCTOR,ACSR,NS,1/0,6/1STR,RAVEN,36" | U176: STR
F177: 7397578 | G177: 114403 | K177: 7991670 | L177: POLE, STEEL, 90FT, CLASS EH9 | M177: LLM | P177: 1580413 | Q177: GUY,DE,AUTO,STRANDVISE,1/2"EHS/7#6AW,SB
F178: 8240446 | G178: 114402 | K178: 7991671 | L178: POLE, STEEL, 95FT, CLASS EH4 | M178: LLM | P178: 1600204 | Q178: XARM,STL,11'-8",115/138KV,GALV ASSY
F179: 7364338 | G179: 114401 | K179: 7991672 | L179: POLE, STEEL, 95FT, CLASS H5 | M179: LLM | P179: 1614255 | Q179: POLE,WOOD,25 FT,CLASS 5,DISTRIBUTION
F180: 7310721 | G180: 114400 | K180: 7991673 | L180: POLE, STEEL, 95FT, CLASS H6 | M180: LLM | P180: 1614354 | Q180: POLE,WOOD,35FT,CLASS 4,DISTRIBUTION
F181: 7295751 | G181: 114399 | K181: 7991674 | L181: POLE, STEEL, 95FT, CLASS EH7 | M181: LLM | P181: 1614402 | Q181: POLE,STEEL,40FT,CLASS 2,DISTRIBUTION
F182: 7310719 | G182: 114398 | K182: 7991675 | L182: POLE, STEEL, 95FT, CLASS EH8 | M182: LLM | P182: 1614403 | Q182: POLE,WOOD,40 FT,CLASS 3,DISTRIBUTION
F183: 7153769 | G183: 114397 | K183: 7991676 | L183: POLE, STEEL, 95FT, CLASS EH9 | M183: LLM | P183: 1614453 | Q183: POLE,WOOD,45FT,CLASS 3,DISTRIBUTION
F184: 7368954 | G184: 114396 | K184: 7991677 | L184: POLE, STEEL, 100FT, CLASS H4 | M184: LLM | P184: 1614454 | Q184: POLE,WOOD,45 FT,CLASS 4,DISTRIBUTION
F185: 7368951 | G185: 114395 | K185: 7991678 | L185: POLE, STEEL, 100FT, CLASS H5 | M185: LLM | P185: 1616501 | Q185: POLE,WOOD,50 FT,CLASS 1,TRANSMISSION
F186: 7153798 | G186: 114394 | K186: 7991679 | L186: POLE, STEEL, 100FT, CLASS H6 | M186: LLM | P186: 1616502 | Q186: POLE,WOOD,50 FT,CLASS 2,TRANSMISSION
F187: 7128432 | G187: 114393 | K187: 7991680 | L187: POLE, STEEL, 100FT, CLASS EH7 | M187: LLM | P187: 1616503 | Q187: POLE,WOOD,50FT,CLASS 3,TRANSMISSION
F188: 7368955 | G188: 114392 | K188: 7991681 | L188: POLE, STEEL, 100FT, CLASS EH8 | M188: LLM | P188: 1616551 | Q188: POLE,WOOD,55 FT,CLASS 1,TRANSMISSION
... F224: 7017207 | G224: 114356 | K224: 7999194 | L224: CONDUCTOR,ACSR,NS,1/0,6/1STR,RAVEN,36" | M224: LLM | P224: 1950526 | Q224: BUS,INSUL,SEC,SUBMERSIBLE,6 POSN,1000A
F225: 6802284 | G225: 114355 | K225: VACSWITCH | L225: 115KV VACUUM 3BOTTLE SWITCH | M225: LLM | P225: 2029350 | Q225: SCREW,TAPPING,#8 X 1",STAINLESS STEEL
F226: 7011447 | G226: 114354 | K226: 4500203 | L226: XFMR,POLE,37.5,12.0,277,NT,ARR | M226: LLM | P226: 2200038 | Q226: FUSE,PWR,SMU-20,14.4KV,65E AMP,SLOW
F227: 8077677 | G227: 114353 | K227: 795591 | L227: FUSE,PWR,SMU-20,34.5KV,15A,TCC 119-2 | M227: LLM | P227: 2200053 | Q227: SWITCH,DISC,INLINE,25KV,600A,150KVBIL
...
